Yasin
Mon, 01 Jan 2024 18:22:36 +0300
----
2024-01-01 18:22:36+03:00
Yasin
Mon, 01 Jan 2024 18:22:29 +0300
----
2024-01-01 18:22:29+03:00
Yasin
Mon, 01 Jan 2024 18:22:14 +0300
----
2024-01-01 18:22:14+03:00
Yasin
Mon, 01 Jan 2024 18:21:52 +0300
----
2024-01-01 18:21:52+03:00
Yasin
Mon, 01 Jan 2024 18:20:27 +0300
----
2024-01-01 18:20:27+03:00
Yasin
Mon, 01 Jan 2024 18:19:03 +0300
----
2024-01-01 18:19:03+03:00
Yasin
Mon, 01 Jan 2024 18:19:41 +0100
----
2024-01-01 18:19:41+01:00
Yasin
Mon, 01 Jan 2024 18:15:00 +0300
----
2024-01-01 18:15:00+03:00
Yasin
Mon, 01 Jan 2024 18:33:34 +0300
----
2024-01-01 18:33:34+03:00
Yasin
Mon, 01 Jan 2024 18:13:24 +0300
----
2024-01-01 18:13:24+03:00
Yasin
Mon, 01 Jan 2024 18:33:01 +0300
----
2024-01-01 18:33:01+03:00
Yasin
Mon, 01 Jan 2024 18:13:11 +0300
----
2024-01-01 18:13:11+03:00
Yasin
Mon, 01 Jan 2024 16:31:02 +0100
----
2024-01-01 16:31:02+01:00
Yasin
Mon, 01 Jan 2024 18:11:17 +0300
----
2024-01-01 18:11:17+03:00
Yasin
Mon, 01 Jan 2024 18:30:44 +0300
----
2024-01-01 18:30:44+03:00
Yasin
Mon, 01 Jan 2024 18:10:48 +0300
----
2024-01-01 18:10:48+03:00
Yasin
Mon, 01 Jan 2024 18:30:34 +0300
----
2024-01-01 18:30:34+03:00
Yasin
Mon, 01 Jan 2024 18:30:11 +0300
----
2024-01-01 18:30:11+03:00
Yasin
Mon, 01 Jan 2024 18:10:20 +0300
----
2024-01-01 18:10:20+03:00
Yasin
Mon, 01 Jan 2024 18:29:57 +0300
----
2024-01-01 18:29:57+03:00
Yasin
Mon, 01 Jan 2024 18:28:35 +0300
----
2024-01-01 18:28:35+03:00
Yasin
Mon, 01 Jan 2024 18:28:06 +0300
----
2024-01-01 18:28:06+03:00
Yasin
Mon, 01 Jan 2024 18:28:05 +0300
----
2024-01-01 18:28:05+03:00
Yasin
Mon, 01 Jan 2024 18:25:35 +0300
----
2024-01-01 18:25:35+03:00
Yasin
Mon, 01 Jan 2024 18:25:26 +0300
----
2024-01-01 18:25:26+03:00
Internal Server Error: /news/
Traceback (most recent call last):
  File "/Users/yasinalbayrak/PycharmProjects/djangoProject2/venv/lib/python3.9/site-packages/django/core/handlers/exception.py", line 55, in inner
    response = get_response(request)
  File "/Users/yasinalbayrak/PycharmProjects/djangoProject2/venv/lib/python3.9/site-packages/django/core/handlers/base.py", line 197, in _get_response
    response = wrapped_callback(request, *callback_args, **callback_kwargs)
  File "/Users/yasinalbayrak/PycharmProjects/djangoProject2/russianNews/views.py", line 21, in news_list
    fetch_news()
  File "/Users/yasinalbayrak/PycharmProjects/djangoProject2/russianNews/views.py", line 54, in fetch_news
    desc_en = translator.translate(desc_ru, src='ru', dest='en').text
  File "/Users/yasinalbayrak/PycharmProjects/djangoProject2/venv/lib/python3.9/site-packages/googletrans/client.py", line 194, in translate
    data, response = self._translate(text, dest, src)
  File "/Users/yasinalbayrak/PycharmProjects/djangoProject2/venv/lib/python3.9/site-packages/googletrans/client.py", line 120, in _translate
    r = self.client.post(url, params=params, data=data)
  File "/Users/yasinalbayrak/PycharmProjects/djangoProject2/venv/lib/python3.9/site-packages/httpx/_client.py", line 824, in post
    return self.request(
  File "/Users/yasinalbayrak/PycharmProjects/djangoProject2/venv/lib/python3.9/site-packages/httpx/_client.py", line 600, in request
    return self.send(
  File "/Users/yasinalbayrak/PycharmProjects/djangoProject2/venv/lib/python3.9/site-packages/httpx/_client.py", line 620, in send
    response = self.send_handling_redirects(
  File "/Users/yasinalbayrak/PycharmProjects/djangoProject2/venv/lib/python3.9/site-packages/httpx/_client.py", line 647, in send_handling_redirects
    response = self.send_handling_auth(
  File "/Users/yasinalbayrak/PycharmProjects/djangoProject2/venv/lib/python3.9/site-packages/httpx/_client.py", line 684, in send_handling_auth
    response = self.send_single_request(request, timeout)
  File "/Users/yasinalbayrak/PycharmProjects/djangoProject2/venv/lib/python3.9/site-packages/httpx/_client.py", line 714, in send_single_request
    ) = transport.request(
  File "/Users/yasinalbayrak/PycharmProjects/djangoProject2/venv/lib/python3.9/site-packages/httpcore/_sync/connection_pool.py", line 152, in request
    response = connection.request(
  File "/Users/yasinalbayrak/PycharmProjects/djangoProject2/venv/lib/python3.9/site-packages/httpcore/_sync/connection.py", line 78, in request
    return self.connection.request(method, url, headers, stream, timeout)
  File "/Users/yasinalbayrak/PycharmProjects/djangoProject2/venv/lib/python3.9/site-packages/httpcore/_sync/http2.py", line 118, in request
    return h2_stream.request(method, url, headers, stream, timeout)
  File "/Users/yasinalbayrak/PycharmProjects/djangoProject2/venv/lib/python3.9/site-packages/httpcore/_sync/http2.py", line 292, in request
    status_code, headers = self.receive_response(timeout)
  File "/Users/yasinalbayrak/PycharmProjects/djangoProject2/venv/lib/python3.9/site-packages/httpcore/_sync/http2.py", line 344, in receive_response
    event = self.connection.wait_for_event(self.stream_id, timeout)
  File "/Users/yasinalbayrak/PycharmProjects/djangoProject2/venv/lib/python3.9/site-packages/httpcore/_sync/http2.py", line 197, in wait_for_event
    self.receive_events(timeout)
  File "/Users/yasinalbayrak/PycharmProjects/djangoProject2/venv/lib/python3.9/site-packages/httpcore/_sync/http2.py", line 204, in receive_events
    data = self.socket.read(self.READ_NUM_BYTES, timeout)
  File "/Users/yasinalbayrak/PycharmProjects/djangoProject2/venv/lib/python3.9/site-packages/httpcore/_backends/sync.py", line 62, in read
    return self.sock.recv(n)
  File "/Library/Developer/CommandLineTools/Library/Frameworks/Python3.framework/Versions/3.9/lib/python3.9/contextlib.py", line 135, in __exit__
    self.gen.throw(type, value, traceback)
  File "/Users/yasinalbayrak/PycharmProjects/djangoProject2/venv/lib/python3.9/site-packages/httpcore/_exceptions.py", line 12, in map_exceptions
    raise to_exc(exc) from None
httpcore._exceptions.ReadTimeout: The read operation timed out
Yasin
Mon, 01 Jan 2024 18:25:24 +0300
----
2024-01-01 18:25:24+03:00
Yasin
Mon, 01 Jan 2024 18:24:17 +0300
----
2024-01-01 18:24:17+03:00
Yasin
Mon, 01 Jan 2024 18:23:44 +0300
----
2024-01-01 18:23:44+03:00
Yasin
Mon, 01 Jan 2024 18:22:59 +0300
----
2024-01-01 18:22:59+03:00
Yasin
Mon, 01 Jan 2024 18:22:36 +0300
----
2024-01-01 18:22:36+03:00
Yasin
Mon, 01 Jan 2024 18:22:29 +0300
----
2024-01-01 18:22:29+03:00
Yasin
Mon, 01 Jan 2024 18:22:14 +0300
----
2024-01-01 18:22:14+03:00
Yasin
Mon, 01 Jan 2024 18:21:52 +0300
----
2024-01-01 18:21:52+03:00
Yasin
Mon, 01 Jan 2024 18:20:27 +0300
----
2024-01-01 18:20:27+03:00
Yasin
Mon, 01 Jan 2024 18:19:03 +0300
----
2024-01-01 18:19:03+03:00
Yasin
Mon, 01 Jan 2024 18:15:00 +0300
----
2024-01-01 18:15:00+03:00
Yasin
Mon, 01 Jan 2024 18:13:24 +0300
----
2024-01-01 18:13:24+03:00
Yasin
Mon, 01 Jan 2024 18:13:11 +0300
----
2024-01-01 18:13:11+03:00
Yasin
Mon, 01 Jan 2024 18:11:17 +0300
----
2024-01-01 18:11:17+03:00
Yasin
Mon, 01 Jan 2024 18:10:48 +0300
----
2024-01-01 18:10:48+03:00
Yasin
Mon, 01 Jan 2024 18:10:20 +0300
----
2024-01-01 18:10:20+03:00
Yasin
Mon, 01 Jan 2024 18:10:10 +0300
----
2024-01-01 18:10:10+03:00
Yasin
Mon, 01 Jan 2024 18:09:14 +0300
----
2024-01-01 18:09:14+03:00
Yasin
Mon, 01 Jan 2024 18:08:38 +0300
----
2024-01-01 18:08:38+03:00
Yasin
Mon, 01 Jan 2024 18:07:35 +0300
----
2024-01-01 18:07:35+03:00
Yasin
Mon, 01 Jan 2024 18:04:40 +0300
----
2024-01-01 18:04:40+03:00
Yasin
Mon, 01 Jan 2024 18:02:30 +0300
----
2024-01-01 18:02:30+03:00
Yasin
Mon, 01 Jan 2024 18:01:02 +0300
----
2024-01-01 18:01:02+03:00
Yasin
Mon, 01 Jan 2024 17:59:39 +0300
----
2024-01-01 17:59:39+03:00
Yasin
Mon, 01 Jan 2024 17:59:17 +0300
----
2024-01-01 17:59:17+03:00
Yasin
Mon, 01 Jan 2024 17:59:14 +0300
----
2024-01-01 17:59:14+03:00
Yasin
Mon, 01 Jan 2024 17:58:36 +0300
----
2024-01-01 17:58:36+03:00
Yasin
Mon, 01 Jan 2024 17:56:04 +0300
----
2024-01-01 17:56:04+03:00
Yasin
Mon, 01 Jan 2024 17:55:39 +0300
----
2024-01-01 17:55:39+03:00
Yasin
Mon, 01 Jan 2024 17:53:54 +0300
----
2024-01-01 17:53:54+03:00
Yasin
Mon, 01 Jan 2024 17:52:44 +0300
----
2024-01-01 17:52:44+03:00
Yasin
Mon, 01 Jan 2024 17:51:36 +0300
----
2024-01-01 17:51:36+03:00
Yasin
Mon, 01 Jan 2024 17:51:15 +0300
----
2024-01-01 17:51:15+03:00
Yasin
Mon, 01 Jan 2024 17:50:57 +0300
----
2024-01-01 17:50:57+03:00
Yasin
Mon, 01 Jan 2024 17:50:18 +0300
----
2024-01-01 17:50:18+03:00
Yasin
Mon, 01 Jan 2024 17:48:41 +0300
----
2024-01-01 17:48:41+03:00
Yasin
Mon, 01 Jan 2024 17:47:54 +0300
----
2024-01-01 17:47:54+03:00
Yasin
Mon, 01 Jan 2024 17:47:49 +0300
----
2024-01-01 17:47:49+03:00
Yasin
Mon, 01 Jan 2024 17:46:46 +0300
----
2024-01-01 17:46:46+03:00
Yasin
Mon, 01 Jan 2024 17:46:19 +0300
----
2024-01-01 17:46:19+03:00
Yasin
Mon, 01 Jan 2024 17:43:26 +0300
----
2024-01-01 17:43:26+03:00
Yasin
Mon, 01 Jan 2024 17:42:22 +0300
----
2024-01-01 17:42:22+03:00
Yasin
Mon, 01 Jan 2024 17:42:21 +0300
----
2024-01-01 17:42:21+03:00
Yasin
Mon, 01 Jan 2024 17:39:18 +0300
----
2024-01-01 17:39:18+03:00
Yasin
Mon, 01 Jan 2024 17:37:55 +0300
----
2024-01-01 17:37:55+03:00
Yasin
Mon, 01 Jan 2024 17:34:12 +0300
----
2024-01-01 17:34:12+03:00
Yasin
Mon, 01 Jan 2024 17:32:48 +0300
----
2024-01-01 17:32:48+03:00
/Users/yasinalbayrak/PycharmProjects/djangoProject2/russianNews/views.py changed, reloading.
Watching for file changes with StatReloader
Yasin
Mon, 01 Jan 2024 18:35:26 +0300
----
2024-01-01 18:35:26+03:00
Yasin
Mon, 01 Jan 2024 18:34:55 +0300
----
2024-01-01 18:34:55+03:00
Yasin
Mon, 01 Jan 2024 18:34:55 +0300
----
2024-01-01 18:34:55+03:00
Yasin
Mon, 01 Jan 2024 17:32:48 +0300
----
2024-01-01 17:32:48+03:00
Yasin
Mon, 01 Jan 2024 17:32:09 +0300
----
2024-01-01 17:32:09+03:00
Yasin
Mon, 01 Jan 2024 17:31:17 +0300
----
2024-01-01 17:31:17+03:00
Yasin
Mon, 01 Jan 2024 17:30:32 +0300
----
2024-01-01 17:30:32+03:00
Yasin
Mon, 01 Jan 2024 17:28:45 +0300
----
2024-01-01 17:28:45+03:00
Yasin
Mon, 01 Jan 2024 17:23:43 +0300
----
2024-01-01 17:23:43+03:00
Yasin
Mon, 01 Jan 2024 17:22:37 +0300
----
2024-01-01 17:22:37+03:00
Yasin
Mon, 01 Jan 2024 17:21:09 +0300
----
2024-01-01 17:21:09+03:00
Yasin
Mon, 01 Jan 2024 17:19:11 +0300
----
2024-01-01 17:19:11+03:00
Yasin
Mon, 01 Jan 2024 18:18:09 +0400
----
2024-01-01 18:18:09+04:00
Yasin
Mon, 01 Jan 2024 17:18:08 +0300
----
2024-01-01 17:18:08+03:00
Yasin
Mon, 01 Jan 2024 17:17:39 +0300
----
2024-01-01 17:17:39+03:00
Yasin
Mon, 01 Jan 2024 18:17:14 +0400
----
2024-01-01 18:17:14+04:00
Yasin
Mon, 01 Jan 2024 18:08:30 +0300
----
2024-01-01 18:08:30+03:00
Yasin
Mon, 01 Jan 2024 18:08:30 +0300
----
2024-01-01 18:08:30+03:00
Yasin
Mon, 01 Jan 2024 18:40:02 +0300
----
2024-01-01 18:40:02+03:00
Yasin
Mon, 01 Jan 2024 18:39:37 +0300
----
2024-01-01 18:39:37+03:00
Yasin
Mon, 01 Jan 2024 18:39:24 +0300
----
2024-01-01 18:39:24+03:00
/Users/yasinalbayrak/PycharmProjects/djangoProject2/russianNews/views.py changed, reloading.
Watching for file changes with StatReloader
/Users/yasinalbayrak/PycharmProjects/djangoProject2/russianNews/views.py changed, reloading.
Watching for file changes with StatReloader
/Users/yasinalbayrak/PycharmProjects/djangoProject2/russianNews/views.py changed, reloading.
Watching for file changes with StatReloader
Internal Server Error: /news/
Traceback (most recent call last):
  File "/Users/yasinalbayrak/PycharmProjects/djangoProject2/venv/lib/python3.9/site-packages/django/template/base.py", line 505, in parse
    compile_func = self.tags[command]
KeyError: 'get_current_language'

During handling of the above exception, another exception occurred:

Traceback (most recent call last):
  File "/Users/yasinalbayrak/PycharmProjects/djangoProject2/venv/lib/python3.9/site-packages/django/core/handlers/exception.py", line 55, in inner
    response = get_response(request)
  File "/Users/yasinalbayrak/PycharmProjects/djangoProject2/venv/lib/python3.9/site-packages/django/core/handlers/base.py", line 197, in _get_response
    response = wrapped_callback(request, *callback_args, **callback_kwargs)
  File "/Users/yasinalbayrak/PycharmProjects/djangoProject2/russianNews/views.py", line 23, in news_list
    return render(request, 'news_list.html', {'news_items': news_items})
  File "/Users/yasinalbayrak/PycharmProjects/djangoProject2/venv/lib/python3.9/site-packages/django/shortcuts.py", line 24, in render
    content = loader.render_to_string(template_name, context, request, using=using)
  File "/Users/yasinalbayrak/PycharmProjects/djangoProject2/venv/lib/python3.9/site-packages/django/template/loader.py", line 61, in render_to_string
    template = get_template(template_name, using=using)
  File "/Users/yasinalbayrak/PycharmProjects/djangoProject2/venv/lib/python3.9/site-packages/django/template/loader.py", line 15, in get_template
    return engine.get_template(template_name)
  File "/Users/yasinalbayrak/PycharmProjects/djangoProject2/venv/lib/python3.9/site-packages/django/template/backends/django.py", line 33, in get_template
    return Template(self.engine.get_template(template_name), self)
  File "/Users/yasinalbayrak/PycharmProjects/djangoProject2/venv/lib/python3.9/site-packages/django/template/engine.py", line 175, in get_template
    template, origin = self.find_template(template_name)
  File "/Users/yasinalbayrak/PycharmProjects/djangoProject2/venv/lib/python3.9/site-packages/django/template/engine.py", line 157, in find_template
    template = loader.get_template(name, skip=skip)
  File "/Users/yasinalbayrak/PycharmProjects/djangoProject2/venv/lib/python3.9/site-packages/django/template/loaders/cached.py", line 57, in get_template
    template = super().get_template(template_name, skip)
  File "/Users/yasinalbayrak/PycharmProjects/djangoProject2/venv/lib/python3.9/site-packages/django/template/loaders/base.py", line 28, in get_template
    return Template(
  File "/Users/yasinalbayrak/PycharmProjects/djangoProject2/venv/lib/python3.9/site-packages/django/template/base.py", line 154, in __init__
    self.nodelist = self.compile_nodelist()
  File "/Users/yasinalbayrak/PycharmProjects/djangoProject2/venv/lib/python3.9/site-packages/django/template/base.py", line 200, in compile_nodelist
    return parser.parse()
  File "/Users/yasinalbayrak/PycharmProjects/djangoProject2/venv/lib/python3.9/site-packages/django/template/base.py", line 507, in parse
    self.invalid_block_tag(token, command, parse_until)
  File "/Users/yasinalbayrak/PycharmProjects/djangoProject2/venv/lib/python3.9/site-packages/django/template/base.py", line 568, in invalid_block_tag
    raise self.error(
django.template.exceptions.TemplateSyntaxError: Invalid block tag on line 72: 'get_current_language'. Did you forget to register or load this tag?
Watching for file changes with StatReloader
/Users/yasinalbayrak/PycharmProjects/djangoProject2/russianNews/views.py changed, reloading.
Watching for file changes with StatReloader
Watching for file changes with StatReloader
/Users/yasinalbayrak/PycharmProjects/djangoProject2/russianNews/views.py changed, reloading.
Watching for file changes with StatReloader
Internal Server Error: /news/
Traceback (most recent call last):
  File "/Users/yasinalbayrak/PycharmProjects/djangoProject2/venv/lib/python3.9/site-packages/django/template/base.py", line 505, in parse
    compile_func = self.tags[command]
KeyError: 'get_current_language'

During handling of the above exception, another exception occurred:

Traceback (most recent call last):
  File "/Users/yasinalbayrak/PycharmProjects/djangoProject2/venv/lib/python3.9/site-packages/django/core/handlers/exception.py", line 55, in inner
    response = get_response(request)
  File "/Users/yasinalbayrak/PycharmProjects/djangoProject2/venv/lib/python3.9/site-packages/django/core/handlers/base.py", line 197, in _get_response
    response = wrapped_callback(request, *callback_args, **callback_kwargs)
  File "/Users/yasinalbayrak/PycharmProjects/djangoProject2/russianNews/views.py", line 23, in news_list
    return render(request, 'news_list.html', {'news_items': news_items})
  File "/Users/yasinalbayrak/PycharmProjects/djangoProject2/venv/lib/python3.9/site-packages/django/shortcuts.py", line 24, in render
    content = loader.render_to_string(template_name, context, request, using=using)
  File "/Users/yasinalbayrak/PycharmProjects/djangoProject2/venv/lib/python3.9/site-packages/django/template/loader.py", line 61, in render_to_string
    template = get_template(template_name, using=using)
  File "/Users/yasinalbayrak/PycharmProjects/djangoProject2/venv/lib/python3.9/site-packages/django/template/loader.py", line 15, in get_template
    return engine.get_template(template_name)
  File "/Users/yasinalbayrak/PycharmProjects/djangoProject2/venv/lib/python3.9/site-packages/django/template/backends/django.py", line 33, in get_template
    return Template(self.engine.get_template(template_name), self)
  File "/Users/yasinalbayrak/PycharmProjects/djangoProject2/venv/lib/python3.9/site-packages/django/template/engine.py", line 175, in get_template
    template, origin = self.find_template(template_name)
  File "/Users/yasinalbayrak/PycharmProjects/djangoProject2/venv/lib/python3.9/site-packages/django/template/engine.py", line 157, in find_template
    template = loader.get_template(name, skip=skip)
  File "/Users/yasinalbayrak/PycharmProjects/djangoProject2/venv/lib/python3.9/site-packages/django/template/loaders/cached.py", line 57, in get_template
    template = super().get_template(template_name, skip)
  File "/Users/yasinalbayrak/PycharmProjects/djangoProject2/venv/lib/python3.9/site-packages/django/template/loaders/base.py", line 28, in get_template
    return Template(
  File "/Users/yasinalbayrak/PycharmProjects/djangoProject2/venv/lib/python3.9/site-packages/django/template/base.py", line 154, in __init__
    self.nodelist = self.compile_nodelist()
  File "/Users/yasinalbayrak/PycharmProjects/djangoProject2/venv/lib/python3.9/site-packages/django/template/base.py", line 200, in compile_nodelist
    return parser.parse()
  File "/Users/yasinalbayrak/PycharmProjects/djangoProject2/venv/lib/python3.9/site-packages/django/template/base.py", line 507, in parse
    self.invalid_block_tag(token, command, parse_until)
  File "/Users/yasinalbayrak/PycharmProjects/djangoProject2/venv/lib/python3.9/site-packages/django/template/base.py", line 568, in invalid_block_tag
    raise self.error(
django.template.exceptions.TemplateSyntaxError: Invalid block tag on line 72: 'get_current_language'. Did you forget to register or load this tag?
Internal Server Error: /news/
Traceback (most recent call last):
  File "/Users/yasinalbayrak/PycharmProjects/djangoProject2/venv/lib/python3.9/site-packages/django/template/base.py", line 505, in parse
    compile_func = self.tags[command]
KeyError: 'get_current_language'

During handling of the above exception, another exception occurred:

Traceback (most recent call last):
  File "/Users/yasinalbayrak/PycharmProjects/djangoProject2/venv/lib/python3.9/site-packages/django/core/handlers/exception.py", line 55, in inner
    response = get_response(request)
  File "/Users/yasinalbayrak/PycharmProjects/djangoProject2/venv/lib/python3.9/site-packages/django/core/handlers/base.py", line 197, in _get_response
    response = wrapped_callback(request, *callback_args, **callback_kwargs)
  File "/Users/yasinalbayrak/PycharmProjects/djangoProject2/russianNews/views.py", line 23, in news_list
    return render(request, 'news_list.html', {'news_items': news_items})
  File "/Users/yasinalbayrak/PycharmProjects/djangoProject2/venv/lib/python3.9/site-packages/django/shortcuts.py", line 24, in render
    content = loader.render_to_string(template_name, context, request, using=using)
  File "/Users/yasinalbayrak/PycharmProjects/djangoProject2/venv/lib/python3.9/site-packages/django/template/loader.py", line 61, in render_to_string
    template = get_template(template_name, using=using)
  File "/Users/yasinalbayrak/PycharmProjects/djangoProject2/venv/lib/python3.9/site-packages/django/template/loader.py", line 15, in get_template
    return engine.get_template(template_name)
  File "/Users/yasinalbayrak/PycharmProjects/djangoProject2/venv/lib/python3.9/site-packages/django/template/backends/django.py", line 33, in get_template
    return Template(self.engine.get_template(template_name), self)
  File "/Users/yasinalbayrak/PycharmProjects/djangoProject2/venv/lib/python3.9/site-packages/django/template/engine.py", line 175, in get_template
    template, origin = self.find_template(template_name)
  File "/Users/yasinalbayrak/PycharmProjects/djangoProject2/venv/lib/python3.9/site-packages/django/template/engine.py", line 157, in find_template
    template = loader.get_template(name, skip=skip)
  File "/Users/yasinalbayrak/PycharmProjects/djangoProject2/venv/lib/python3.9/site-packages/django/template/loaders/cached.py", line 57, in get_template
    template = super().get_template(template_name, skip)
  File "/Users/yasinalbayrak/PycharmProjects/djangoProject2/venv/lib/python3.9/site-packages/django/template/loaders/base.py", line 28, in get_template
    return Template(
  File "/Users/yasinalbayrak/PycharmProjects/djangoProject2/venv/lib/python3.9/site-packages/django/template/base.py", line 154, in __init__
    self.nodelist = self.compile_nodelist()
  File "/Users/yasinalbayrak/PycharmProjects/djangoProject2/venv/lib/python3.9/site-packages/django/template/base.py", line 200, in compile_nodelist
    return parser.parse()
  File "/Users/yasinalbayrak/PycharmProjects/djangoProject2/venv/lib/python3.9/site-packages/django/template/base.py", line 507, in parse
    self.invalid_block_tag(token, command, parse_until)
  File "/Users/yasinalbayrak/PycharmProjects/djangoProject2/venv/lib/python3.9/site-packages/django/template/base.py", line 568, in invalid_block_tag
    raise self.error(
django.template.exceptions.TemplateSyntaxError: Invalid block tag on line 72: 'get_current_language'. Did you forget to register or load this tag?
/Users/yasinalbayrak/PycharmProjects/djangoProject2/djangoProject2/settings.py changed, reloading.
Watching for file changes with StatReloader
Internal Server Error: /news/
Traceback (most recent call last):
  File "/Users/yasinalbayrak/PycharmProjects/djangoProject2/venv/lib/python3.9/site-packages/django/template/base.py", line 505, in parse
    compile_func = self.tags[command]
KeyError: 'get_current_language'

During handling of the above exception, another exception occurred:

Traceback (most recent call last):
  File "/Users/yasinalbayrak/PycharmProjects/djangoProject2/venv/lib/python3.9/site-packages/django/core/handlers/exception.py", line 55, in inner
    response = get_response(request)
  File "/Users/yasinalbayrak/PycharmProjects/djangoProject2/venv/lib/python3.9/site-packages/django/core/handlers/base.py", line 197, in _get_response
    response = wrapped_callback(request, *callback_args, **callback_kwargs)
  File "/Users/yasinalbayrak/PycharmProjects/djangoProject2/russianNews/views.py", line 23, in news_list
    return render(request, 'news_list.html', {'news_items': news_items})
  File "/Users/yasinalbayrak/PycharmProjects/djangoProject2/venv/lib/python3.9/site-packages/django/shortcuts.py", line 24, in render
    content = loader.render_to_string(template_name, context, request, using=using)
  File "/Users/yasinalbayrak/PycharmProjects/djangoProject2/venv/lib/python3.9/site-packages/django/template/loader.py", line 61, in render_to_string
    template = get_template(template_name, using=using)
  File "/Users/yasinalbayrak/PycharmProjects/djangoProject2/venv/lib/python3.9/site-packages/django/template/loader.py", line 15, in get_template
    return engine.get_template(template_name)
  File "/Users/yasinalbayrak/PycharmProjects/djangoProject2/venv/lib/python3.9/site-packages/django/template/backends/django.py", line 33, in get_template
    return Template(self.engine.get_template(template_name), self)
  File "/Users/yasinalbayrak/PycharmProjects/djangoProject2/venv/lib/python3.9/site-packages/django/template/engine.py", line 175, in get_template
    template, origin = self.find_template(template_name)
  File "/Users/yasinalbayrak/PycharmProjects/djangoProject2/venv/lib/python3.9/site-packages/django/template/engine.py", line 157, in find_template
    template = loader.get_template(name, skip=skip)
  File "/Users/yasinalbayrak/PycharmProjects/djangoProject2/venv/lib/python3.9/site-packages/django/template/loaders/cached.py", line 57, in get_template
    template = super().get_template(template_name, skip)
  File "/Users/yasinalbayrak/PycharmProjects/djangoProject2/venv/lib/python3.9/site-packages/django/template/loaders/base.py", line 28, in get_template
    return Template(
  File "/Users/yasinalbayrak/PycharmProjects/djangoProject2/venv/lib/python3.9/site-packages/django/template/base.py", line 154, in __init__
    self.nodelist = self.compile_nodelist()
  File "/Users/yasinalbayrak/PycharmProjects/djangoProject2/venv/lib/python3.9/site-packages/django/template/base.py", line 200, in compile_nodelist
    return parser.parse()
  File "/Users/yasinalbayrak/PycharmProjects/djangoProject2/venv/lib/python3.9/site-packages/django/template/base.py", line 507, in parse
    self.invalid_block_tag(token, command, parse_until)
  File "/Users/yasinalbayrak/PycharmProjects/djangoProject2/venv/lib/python3.9/site-packages/django/template/base.py", line 568, in invalid_block_tag
    raise self.error(
django.template.exceptions.TemplateSyntaxError: Invalid block tag on line 72: 'get_current_language'. Did you forget to register or load this tag?
/Users/yasinalbayrak/PycharmProjects/djangoProject2/russianNews/models.py changed, reloading.
Watching for file changes with StatReloader
Not Found: /home/
/Users/yasinalbayrak/PycharmProjects/djangoProject2/djangoProject2/urls.py changed, reloading.
Watching for file changes with StatReloader
/Users/yasinalbayrak/PycharmProjects/djangoProject2/russianNews/views.py changed, reloading.
Watching for file changes with StatReloader
Internal Server Error: /news/
Traceback (most recent call last):
  File "/Users/yasinalbayrak/PycharmProjects/djangoProject2/venv/lib/python3.9/site-packages/django/core/handlers/exception.py", line 55, in inner
    response = get_response(request)
  File "/Users/yasinalbayrak/PycharmProjects/djangoProject2/venv/lib/python3.9/site-packages/django/core/handlers/base.py", line 197, in _get_response
    response = wrapped_callback(request, *callback_args, **callback_kwargs)
  File "/Users/yasinalbayrak/PycharmProjects/djangoProject2/russianNews/views.py", line 21, in news_list
    fetch_news()
  File "/Users/yasinalbayrak/PycharmProjects/djangoProject2/russianNews/views.py", line 49, in fetch_news
    title_en = translator.translate(title_ru, src='ru', dest='en').text
  File "/Users/yasinalbayrak/PycharmProjects/djangoProject2/venv/lib/python3.9/site-packages/googletrans/client.py", line 194, in translate
    data, response = self._translate(text, dest, src)
  File "/Users/yasinalbayrak/PycharmProjects/djangoProject2/venv/lib/python3.9/site-packages/googletrans/client.py", line 120, in _translate
    r = self.client.post(url, params=params, data=data)
  File "/Users/yasinalbayrak/PycharmProjects/djangoProject2/venv/lib/python3.9/site-packages/httpx/_client.py", line 824, in post
    return self.request(
  File "/Users/yasinalbayrak/PycharmProjects/djangoProject2/venv/lib/python3.9/site-packages/httpx/_client.py", line 600, in request
    return self.send(
  File "/Users/yasinalbayrak/PycharmProjects/djangoProject2/venv/lib/python3.9/site-packages/httpx/_client.py", line 620, in send
    response = self.send_handling_redirects(
  File "/Users/yasinalbayrak/PycharmProjects/djangoProject2/venv/lib/python3.9/site-packages/httpx/_client.py", line 647, in send_handling_redirects
    response = self.send_handling_auth(
  File "/Users/yasinalbayrak/PycharmProjects/djangoProject2/venv/lib/python3.9/site-packages/httpx/_client.py", line 684, in send_handling_auth
    response = self.send_single_request(request, timeout)
  File "/Users/yasinalbayrak/PycharmProjects/djangoProject2/venv/lib/python3.9/site-packages/httpx/_client.py", line 714, in send_single_request
    ) = transport.request(
  File "/Users/yasinalbayrak/PycharmProjects/djangoProject2/venv/lib/python3.9/site-packages/httpcore/_sync/connection_pool.py", line 152, in request
    response = connection.request(
  File "/Users/yasinalbayrak/PycharmProjects/djangoProject2/venv/lib/python3.9/site-packages/httpcore/_sync/connection.py", line 78, in request
    return self.connection.request(method, url, headers, stream, timeout)
  File "/Users/yasinalbayrak/PycharmProjects/djangoProject2/venv/lib/python3.9/site-packages/httpcore/_sync/http2.py", line 118, in request
    return h2_stream.request(method, url, headers, stream, timeout)
  File "/Users/yasinalbayrak/PycharmProjects/djangoProject2/venv/lib/python3.9/site-packages/httpcore/_sync/http2.py", line 292, in request
    status_code, headers = self.receive_response(timeout)
  File "/Users/yasinalbayrak/PycharmProjects/djangoProject2/venv/lib/python3.9/site-packages/httpcore/_sync/http2.py", line 344, in receive_response
    event = self.connection.wait_for_event(self.stream_id, timeout)
  File "/Users/yasinalbayrak/PycharmProjects/djangoProject2/venv/lib/python3.9/site-packages/httpcore/_sync/http2.py", line 197, in wait_for_event
    self.receive_events(timeout)
  File "/Users/yasinalbayrak/PycharmProjects/djangoProject2/venv/lib/python3.9/site-packages/httpcore/_sync/http2.py", line 204, in receive_events
    data = self.socket.read(self.READ_NUM_BYTES, timeout)
  File "/Users/yasinalbayrak/PycharmProjects/djangoProject2/venv/lib/python3.9/site-packages/httpcore/_backends/sync.py", line 62, in read
    return self.sock.recv(n)
  File "/Library/Developer/CommandLineTools/Library/Frameworks/Python3.framework/Versions/3.9/lib/python3.9/contextlib.py", line 135, in __exit__
    self.gen.throw(type, value, traceback)
  File "/Users/yasinalbayrak/PycharmProjects/djangoProject2/venv/lib/python3.9/site-packages/httpcore/_exceptions.py", line 12, in map_exceptions
    raise to_exc(exc) from None
httpcore._exceptions.ReadTimeout: The read operation timed out
/Users/yasinalbayrak/PycharmProjects/djangoProject2/russianNews/views.py changed, reloading.
Watching for file changes with StatReloader
/Users/yasinalbayrak/PycharmProjects/djangoProject2/russianNews/views.py changed, reloading.
Watching for file changes with StatReloader
/Users/yasinalbayrak/PycharmProjects/djangoProject2/russianNews/views.py changed, reloading.
Watching for file changes with StatReloader
Watching for file changes with StatReloader
Watching for file changes with StatReloader
/Users/yasinalbayrak/PycharmProjects/djangoProject2/russianNews/views.py changed, reloading.
Watching for file changes with StatReloader
Internal Server Error: /news/
Traceback (most recent call last):
  File "/Users/yasinalbayrak/PycharmProjects/djangoProject2/venv/lib/python3.9/site-packages/django/core/handlers/exception.py", line 55, in inner
    response = get_response(request)
  File "/Users/yasinalbayrak/PycharmProjects/djangoProject2/venv/lib/python3.9/site-packages/django/core/handlers/base.py", line 197, in _get_response
    response = wrapped_callback(request, *callback_args, **callback_kwargs)
  File "/Users/yasinalbayrak/PycharmProjects/djangoProject2/russianNews/views.py", line 23, in news_list
    return render(request, 'news_list.html', {'news_items': news_items})
  File "/Users/yasinalbayrak/PycharmProjects/djangoProject2/venv/lib/python3.9/site-packages/django/shortcuts.py", line 24, in render
    content = loader.render_to_string(template_name, context, request, using=using)
  File "/Users/yasinalbayrak/PycharmProjects/djangoProject2/venv/lib/python3.9/site-packages/django/template/loader.py", line 62, in render_to_string
    return template.render(context, request)
  File "/Users/yasinalbayrak/PycharmProjects/djangoProject2/venv/lib/python3.9/site-packages/django/template/backends/django.py", line 61, in render
    return self.template.render(context)
  File "/Users/yasinalbayrak/PycharmProjects/djangoProject2/venv/lib/python3.9/site-packages/django/template/base.py", line 175, in render
    return self._render(context)
  File "/Users/yasinalbayrak/PycharmProjects/djangoProject2/venv/lib/python3.9/site-packages/django/template/base.py", line 167, in _render
    return self.nodelist.render(context)
  File "/Users/yasinalbayrak/PycharmProjects/djangoProject2/venv/lib/python3.9/site-packages/django/template/base.py", line 1005, in render
    return SafeString("".join([node.render_annotated(context) for node in self]))
  File "/Users/yasinalbayrak/PycharmProjects/djangoProject2/venv/lib/python3.9/site-packages/django/template/base.py", line 1005, in <listcomp>
    return SafeString("".join([node.render_annotated(context) for node in self]))
  File "/Users/yasinalbayrak/PycharmProjects/djangoProject2/venv/lib/python3.9/site-packages/django/template/base.py", line 966, in render_annotated
    return self.render(context)
  File "/Users/yasinalbayrak/PycharmProjects/djangoProject2/venv/lib/python3.9/site-packages/django/template/defaulttags.py", line 471, in render
    url = reverse(view_name, args=args, kwargs=kwargs, current_app=current_app)
  File "/Users/yasinalbayrak/PycharmProjects/djangoProject2/venv/lib/python3.9/site-packages/django/urls/base.py", line 88, in reverse
    return resolver._reverse_with_prefix(view, prefix, *args, **kwargs)
  File "/Users/yasinalbayrak/PycharmProjects/djangoProject2/venv/lib/python3.9/site-packages/django/urls/resolvers.py", line 828, in _reverse_with_prefix
    raise NoReverseMatch(msg)
django.urls.exceptions.NoReverseMatch: Reverse for 'search_news' not found. 'search_news' is not a valid view function or pattern name.
/Users/yasinalbayrak/PycharmProjects/djangoProject2/russianNews/views.py changed, reloading.
Watching for file changes with StatReloader
/Users/yasinalbayrak/PycharmProjects/djangoProject2/russianNews/views.py changed, reloading.
Watching for file changes with StatReloader
/Users/yasinalbayrak/PycharmProjects/djangoProject2/russianNews/views.py changed, reloading.
Watching for file changes with StatReloader
/Users/yasinalbayrak/PycharmProjects/djangoProject2/russianNews/views.py changed, reloading.
Watching for file changes with StatReloader
/Users/yasinalbayrak/PycharmProjects/djangoProject2/djangoProject2/settings.py changed, reloading.
Watching for file changes with StatReloader
/Users/yasinalbayrak/PycharmProjects/djangoProject2/djangoProject2/settings.py changed, reloading.
Watching for file changes with StatReloader
/Users/yasinalbayrak/PycharmProjects/djangoProject2/auth_user/views.py changed, reloading.
Watching for file changes with StatReloader
/Users/yasinalbayrak/PycharmProjects/djangoProject2/auth_user/views.py changed, reloading.
Watching for file changes with StatReloader
/Users/yasinalbayrak/PycharmProjects/djangoProject2/djangoProject2/urls.py changed, reloading.
Watching for file changes with StatReloader
/Users/yasinalbayrak/PycharmProjects/djangoProject2/auth_user/views.py changed, reloading.
Watching for file changes with StatReloader
Method Not Allowed: /register/
Internal Server Error: /register
Traceback (most recent call last):
  File "/Users/yasinalbayrak/PycharmProjects/djangoProject2/venv/lib/python3.9/site-packages/django/core/handlers/exception.py", line 55, in inner
    response = get_response(request)
  File "/Users/yasinalbayrak/PycharmProjects/djangoProject2/venv/lib/python3.9/site-packages/django/utils/deprecation.py", line 136, in __call__
    response = self.process_response(request, response)
  File "/Users/yasinalbayrak/PycharmProjects/djangoProject2/venv/lib/python3.9/site-packages/django/middleware/common.py", line 108, in process_response
    return self.response_redirect_class(self.get_full_path_with_slash(request))
  File "/Users/yasinalbayrak/PycharmProjects/djangoProject2/venv/lib/python3.9/site-packages/django/middleware/common.py", line 87, in get_full_path_with_slash
    raise RuntimeError(
RuntimeError: You called this URL via POST, but the URL doesn't end in a slash and you have APPEND_SLASH set. Django can't redirect to the slash URL while maintaining POST data. Change your form to point to 127.0.0.1:8000/register/ (note the trailing slash), or set APPEND_SLASH=False in your Django settings.
/Users/yasinalbayrak/PycharmProjects/djangoProject2/djangoProject2/settings.py changed, reloading.
Watching for file changes with StatReloader
Watching for file changes with StatReloader
Method Not Allowed: /register/
Method Not Allowed: /register/
Method Not Allowed: /register/
Method Not Allowed: /register/
Method Not Allowed: /register/
Method Not Allowed: /register/
Method Not Allowed: /register/
Not Found: /static/rest_framework/css/bootstrap.min.css
Not Found: /static/rest_framework/css/bootstrap-tweaks.css
Not Found: /static/rest_framework/css/prettify.css
Not Found: /static/rest_framework/css/default.css
Not Found: /static/rest_framework/js/jquery-3.5.1.min.js
Not Found: /static/rest_framework/js/ajax-form.js
Not Found: /static/rest_framework/js/csrf.js
Not Found: /static/rest_framework/js/bootstrap.min.js
Not Found: /static/rest_framework/js/prettify-min.js
Not Found: /static/rest_framework/js/default.js
Method Not Allowed: /register/
Not Found: /static/rest_framework/css/bootstrap.min.css
Not Found: /static/rest_framework/css/bootstrap-tweaks.css
Not Found: /static/rest_framework/css/prettify.css
Not Found: /static/rest_framework/css/default.css
Not Found: /static/rest_framework/js/jquery-3.5.1.min.js
Not Found: /static/rest_framework/js/ajax-form.js
Not Found: /static/rest_framework/js/csrf.js
Not Found: /static/rest_framework/js/bootstrap.min.js
Not Found: /static/rest_framework/js/prettify-min.js
Not Found: /static/rest_framework/js/default.js
/Users/yasinalbayrak/PycharmProjects/djangoProject2/auth_user/views.py changed, reloading.
Watching for file changes with StatReloader
Bad Request: /register/
Not Found: /static/rest_framework/css/bootstrap.min.css
Not Found: /static/rest_framework/css/bootstrap-tweaks.css
Not Found: /static/rest_framework/css/prettify.css
Not Found: /static/rest_framework/css/default.css
Not Found: /static/rest_framework/js/jquery-3.5.1.min.js
Not Found: /static/rest_framework/js/ajax-form.js
Not Found: /static/rest_framework/js/csrf.js
Not Found: /static/rest_framework/js/bootstrap.min.js
Not Found: /static/rest_framework/js/prettify-min.js
Not Found: /static/rest_framework/js/default.js
Error in user creation: User() got unexpected keyword arguments: 'first_name', 'last_name'
/Users/yasinalbayrak/PycharmProjects/djangoProject2/auth_user/views.py changed, reloading.
Watching for file changes with StatReloader
Internal Server Error: /register/
Traceback (most recent call last):
  File "/Users/yasinalbayrak/PycharmProjects/djangoProject2/venv/lib/python3.9/site-packages/django/core/handlers/exception.py", line 55, in inner
    response = get_response(request)
  File "/Users/yasinalbayrak/PycharmProjects/djangoProject2/venv/lib/python3.9/site-packages/django/core/handlers/base.py", line 197, in _get_response
    response = wrapped_callback(request, *callback_args, **callback_kwargs)
  File "/Users/yasinalbayrak/PycharmProjects/djangoProject2/auth_user/views.py", line 27, in register
    firstname = request.data.get('fname')
AttributeError: 'WSGIRequest' object has no attribute 'data'
Internal Server Error: /register/
Traceback (most recent call last):
  File "/Users/yasinalbayrak/PycharmProjects/djangoProject2/venv/lib/python3.9/site-packages/django/core/handlers/exception.py", line 55, in inner
    response = get_response(request)
  File "/Users/yasinalbayrak/PycharmProjects/djangoProject2/venv/lib/python3.9/site-packages/django/core/handlers/base.py", line 197, in _get_response
    response = wrapped_callback(request, *callback_args, **callback_kwargs)
  File "/Users/yasinalbayrak/PycharmProjects/djangoProject2/auth_user/views.py", line 27, in register
    firstname = request.data.get('fname')
AttributeError: 'WSGIRequest' object has no attribute 'data'
Internal Server Error: /register/
Traceback (most recent call last):
  File "/Users/yasinalbayrak/PycharmProjects/djangoProject2/venv/lib/python3.9/site-packages/django/core/handlers/exception.py", line 55, in inner
    response = get_response(request)
  File "/Users/yasinalbayrak/PycharmProjects/djangoProject2/venv/lib/python3.9/site-packages/django/core/handlers/base.py", line 197, in _get_response
    response = wrapped_callback(request, *callback_args, **callback_kwargs)
  File "/Users/yasinalbayrak/PycharmProjects/djangoProject2/auth_user/views.py", line 27, in register
    firstname = request.data.get('fname')
AttributeError: 'WSGIRequest' object has no attribute 'data'
/Users/yasinalbayrak/PycharmProjects/djangoProject2/auth_user/views.py changed, reloading.
Watching for file changes with StatReloader
/Users/yasinalbayrak/PycharmProjects/djangoProject2/auth_user/views.py changed, reloading.
Watching for file changes with StatReloader
Internal Server Error: /register/
Traceback (most recent call last):
  File "/Users/yasinalbayrak/PycharmProjects/djangoProject2/venv/lib/python3.9/site-packages/django/core/handlers/exception.py", line 55, in inner
    response = get_response(request)
  File "/Users/yasinalbayrak/PycharmProjects/djangoProject2/venv/lib/python3.9/site-packages/django/core/handlers/base.py", line 197, in _get_response
    response = wrapped_callback(request, *callback_args, **callback_kwargs)
  File "/Users/yasinalbayrak/PycharmProjects/djangoProject2/auth_user/views.py", line 27, in register
    firstname = request.data.get('fname')
AttributeError: 'WSGIRequest' object has no attribute 'data'
Internal Server Error: /register/
Traceback (most recent call last):
  File "/Users/yasinalbayrak/PycharmProjects/djangoProject2/venv/lib/python3.9/site-packages/django/core/handlers/exception.py", line 55, in inner
    response = get_response(request)
  File "/Users/yasinalbayrak/PycharmProjects/djangoProject2/venv/lib/python3.9/site-packages/django/core/handlers/base.py", line 197, in _get_response
    response = wrapped_callback(request, *callback_args, **callback_kwargs)
  File "/Users/yasinalbayrak/PycharmProjects/djangoProject2/auth_user/views.py", line 27, in register
    firstname = request.data.get('fname')
AttributeError: 'WSGIRequest' object has no attribute 'data'
/Users/yasinalbayrak/PycharmProjects/djangoProject2/auth_user/views.py changed, reloading.
Watching for file changes with StatReloader
/Users/yasinalbayrak/PycharmProjects/djangoProject2/auth_user/views.py changed, reloading.
Watching for file changes with StatReloader
/Users/yasinalbayrak/PycharmProjects/djangoProject2/auth_user/views.py changed, reloading.
Watching for file changes with StatReloader
/Users/yasinalbayrak/PycharmProjects/djangoProject2/auth_user/views.py changed, reloading.
Watching for file changes with StatReloader
/Users/yasinalbayrak/PycharmProjects/djangoProject2/auth_user/views.py changed, reloading.
Watching for file changes with StatReloader
/Users/yasinalbayrak/PycharmProjects/djangoProject2/auth_user/views.py changed, reloading.
Watching for file changes with StatReloader
/Users/yasinalbayrak/PycharmProjects/djangoProject2/auth_user/views.py changed, reloading.
Watching for file changes with StatReloader
/Users/yasinalbayrak/PycharmProjects/djangoProject2/auth_user/views.py changed, reloading.
Watching for file changes with StatReloader
/Users/yasinalbayrak/PycharmProjects/djangoProject2/djangoProject2/urls.py changed, reloading.
Watching for file changes with StatReloader
/Users/yasinalbayrak/PycharmProjects/djangoProject2/djangoProject2/settings.py changed, reloading.
Watching for file changes with StatReloader
/Users/yasinalbayrak/PycharmProjects/djangoProject2/auth_user/serializers.py changed, reloading.
Watching for file changes with StatReloader
/Users/yasinalbayrak/PycharmProjects/djangoProject2/auth_user/views.py changed, reloading.
Watching for file changes with StatReloader
/Users/yasinalbayrak/PycharmProjects/djangoProject2/auth_user/views.py changed, reloading.
Watching for file changes with StatReloader
/Users/yasinalbayrak/PycharmProjects/djangoProject2/auth_user/views.py changed, reloading.
Watching for file changes with StatReloader
/Users/yasinalbayrak/PycharmProjects/djangoProject2/auth_user/views.py changed, reloading.
Watching for file changes with StatReloader
/Users/yasinalbayrak/PycharmProjects/djangoProject2/auth_user/views.py changed, reloading.
Watching for file changes with StatReloader
/Users/yasinalbayrak/PycharmProjects/djangoProject2/auth_user/views.py changed, reloading.
Watching for file changes with StatReloader
/Users/yasinalbayrak/PycharmProjects/djangoProject2/auth_user/views.py changed, reloading.
Watching for file changes with StatReloader
/Users/yasinalbayrak/PycharmProjects/djangoProject2/auth_user/views.py changed, reloading.
Watching for file changes with StatReloader
/Users/yasinalbayrak/PycharmProjects/djangoProject2/djangoProject2/urls.py changed, reloading.
Watching for file changes with StatReloader
/Users/yasinalbayrak/PycharmProjects/djangoProject2/djangoProject2/urls.py changed, reloading.
Watching for file changes with StatReloader
/Users/yasinalbayrak/PycharmProjects/djangoProject2/djangoProject2/urls.py changed, reloading.
Watching for file changes with StatReloader
/Users/yasinalbayrak/PycharmProjects/djangoProject2/djangoProject2/urls.py changed, reloading.
Watching for file changes with StatReloader
Unauthorized: /token/create
Bad Request: /token/create
Unauthorized: /token/create
Bad Request: /token/refresh/
Unauthorized: /token/verify
/Users/yasinalbayrak/PycharmProjects/djangoProject2/djangoProject2/settings.py changed, reloading.
Watching for file changes with StatReloader
/Users/yasinalbayrak/PycharmProjects/djangoProject2/auth_user/views.py changed, reloading.
Watching for file changes with StatReloader
/Users/yasinalbayrak/PycharmProjects/djangoProject2/auth_user/views.py changed, reloading.
Watching for file changes with StatReloader
/Users/yasinalbayrak/PycharmProjects/djangoProject2/djangoProject2/settings.py changed, reloading.
Watching for file changes with StatReloader
/Users/yasinalbayrak/PycharmProjects/djangoProject2/djangoProject2/settings.py changed, reloading.
Watching for file changes with StatReloader
/Users/yasinalbayrak/PycharmProjects/djangoProject2/djangoProject2/settings.py changed, reloading.
Watching for file changes with StatReloader
/Users/yasinalbayrak/PycharmProjects/djangoProject2/djangoProject2/settings.py changed, reloading.
Watching for file changes with StatReloader
Watching for file changes with StatReloader
/Users/yasinalbayrak/PycharmProjects/djangoProject2/djangoProject2/settings.py changed, reloading.
Watching for file changes with StatReloader
/Users/yasinalbayrak/PycharmProjects/djangoProject2/auth_user/serializers.py changed, reloading.
Watching for file changes with StatReloader
Unauthorized: /success/
/Users/yasinalbayrak/PycharmProjects/djangoProject2/russianNews/views.py changed, reloading.
Watching for file changes with StatReloader
/Users/yasinalbayrak/PycharmProjects/djangoProject2/auth_user/views.py changed, reloading.
Watching for file changes with StatReloader
/Users/yasinalbayrak/PycharmProjects/djangoProject2/auth_user/views.py changed, reloading.
Watching for file changes with StatReloader
/Users/yasinalbayrak/PycharmProjects/djangoProject2/auth_user/views.py changed, reloading.
Watching for file changes with StatReloader
/Users/yasinalbayrak/PycharmProjects/djangoProject2/auth_user/views.py changed, reloading.
Watching for file changes with StatReloader
/Users/yasinalbayrak/PycharmProjects/djangoProject2/auth_user/views.py changed, reloading.
Watching for file changes with StatReloader
/Users/yasinalbayrak/PycharmProjects/djangoProject2/auth_user/views.py changed, reloading.
Watching for file changes with StatReloader
/Users/yasinalbayrak/PycharmProjects/djangoProject2/auth_user/views.py changed, reloading.
Watching for file changes with StatReloader
/Users/yasinalbayrak/PycharmProjects/djangoProject2/auth_user/views.py changed, reloading.
Watching for file changes with StatReloader
Unauthorized: /news/
User created successfully: yaso
Error in user creation: 'Settings' object has no attribute 'BASE_URL'
Unauthorized: /news/
/Users/yasinalbayrak/PycharmProjects/djangoProject2/djangoProject2/settings.py changed, reloading.
Watching for file changes with StatReloader
User created successfully: yaso2
/Users/yasinalbayrak/PycharmProjects/djangoProject2/auth_user/views.py changed, reloading.
Watching for file changes with StatReloader
User created successfully: yaso3
/Users/yasinalbayrak/PycharmProjects/djangoProject2/auth_user/views.py changed, reloading.
Watching for file changes with StatReloader
Registration failed: Username yasinalbayrak2 already exists
User created successfully: yasinalbayrak3
Unauthorized: /news/
Not Found: /static/rest_framework/css/bootstrap-tweaks.css
Not Found: /static/rest_framework/css/default.css
Not Found: /static/rest_framework/css/prettify.css
Not Found: /static/rest_framework/css/bootstrap.min.css
Not Found: /static/rest_framework/js/jquery-3.5.1.min.js
Not Found: /static/rest_framework/js/csrf.js
Not Found: /static/rest_framework/js/ajax-form.js
Not Found: /static/rest_framework/js/bootstrap.min.js
Not Found: /static/rest_framework/js/prettify-min.js
Not Found: /static/rest_framework/js/default.js
/Users/yasinalbayrak/PycharmProjects/djangoProject2/auth_user/views.py changed, reloading.
Watching for file changes with StatReloader
/Users/yasinalbayrak/PycharmProjects/djangoProject2/auth_user/views.py changed, reloading.
Watching for file changes with StatReloader
User created successfully: yasinalbayrak4
Error in user creation: Reverse for '<WSGIRequest: POST '/register/'>' not found. '<WSGIRequest: POST '/register/'>' is not a valid view function or pattern name.
/Users/yasinalbayrak/PycharmProjects/djangoProject2/auth_user/views.py changed, reloading.
Watching for file changes with StatReloader
/Users/yasinalbayrak/PycharmProjects/djangoProject2/auth_user/views.py changed, reloading.
Watching for file changes with StatReloader
/Users/yasinalbayrak/PycharmProjects/djangoProject2/auth_user/views.py changed, reloading.
Watching for file changes with StatReloader
/Users/yasinalbayrak/PycharmProjects/djangoProject2/auth_user/views.py changed, reloading.
Watching for file changes with StatReloader
/Users/yasinalbayrak/PycharmProjects/djangoProject2/russianNews/views.py changed, reloading.
Watching for file changes with StatReloader
/Users/yasinalbayrak/PycharmProjects/djangoProject2/auth_user/views.py changed, reloading.
Watching for file changes with StatReloader
Registration failed: Username yasinalbayrak3 already exists
Unauthorized: /news/
Not Found: /static/rest_framework/css/bootstrap-tweaks.css
Not Found: /static/rest_framework/css/bootstrap.min.css
Not Found: /static/rest_framework/css/prettify.css
Not Found: /static/rest_framework/css/default.css
Not Found: /static/rest_framework/js/jquery-3.5.1.min.js
Not Found: /static/rest_framework/js/csrf.js
Not Found: /static/rest_framework/js/prettify-min.js
Not Found: /static/rest_framework/js/default.js
Not Found: /static/rest_framework/js/ajax-form.js
Not Found: /static/rest_framework/js/bootstrap.min.js
/Users/yasinalbayrak/PycharmProjects/djangoProject2/russianNews/views.py changed, reloading.
Watching for file changes with StatReloader
Watching for file changes with StatReloader
Not Found: /favicon.ico
Registration failed: Username yasinalbayrak already exists
/Users/yasinalbayrak/PycharmProjects/djangoProject2/russianNews/views.py changed, reloading.
Watching for file changes with StatReloader
/Users/yasinalbayrak/PycharmProjects/djangoProject2/russianNews/views.py changed, reloading.
Watching for file changes with StatReloader
/Users/yasinalbayrak/PycharmProjects/djangoProject2/russianNews/views.py changed, reloading.
Watching for file changes with StatReloader
Unauthorized: /success/
Not Found: /static/rest_framework/css/bootstrap.min.css
Not Found: /static/rest_framework/css/bootstrap-tweaks.css
Not Found: /static/rest_framework/css/prettify.css
Not Found: /static/rest_framework/css/default.css
Not Found: /static/rest_framework/js/jquery-3.5.1.min.js
Not Found: /static/rest_framework/js/csrf.js
Not Found: /static/rest_framework/js/bootstrap.min.js
Not Found: /static/rest_framework/js/prettify-min.js
Not Found: /static/rest_framework/js/ajax-form.js
Not Found: /static/rest_framework/js/default.js
Unauthorized: /success/
Not Found: /static/rest_framework/css/bootstrap.min.css
Not Found: /static/rest_framework/css/bootstrap-tweaks.css
Not Found: /static/rest_framework/js/jquery-3.5.1.min.js
Not Found: /static/rest_framework/js/ajax-form.js
Not Found: /static/rest_framework/css/prettify.css
Not Found: /static/rest_framework/css/default.css
Not Found: /static/rest_framework/js/csrf.js
Not Found: /static/rest_framework/js/bootstrap.min.js
Not Found: /static/rest_framework/js/prettify-min.js
Not Found: /static/rest_framework/js/default.js
/Users/yasinalbayrak/PycharmProjects/djangoProject2/russianNews/views.py changed, reloading.
Watching for file changes with StatReloader
/Users/yasinalbayrak/PycharmProjects/djangoProject2/djangoProject2/urls.py changed, reloading.
Watching for file changes with StatReloader
/Users/yasinalbayrak/PycharmProjects/djangoProject2/russianNews/models.py changed, reloading.
Watching for file changes with StatReloader
/Users/yasinalbayrak/PycharmProjects/djangoProject2/russianNews/views.py changed, reloading.
Watching for file changes with StatReloader
/Users/yasinalbayrak/PycharmProjects/djangoProject2/russianNews/views.py changed, reloading.
Watching for file changes with StatReloader
Watching for file changes with StatReloader
Not Found: /news_detail/
Not Found: /news_detail/1
Internal Server Error: /news/1/
Traceback (most recent call last):
  File "/Users/yasinalbayrak/PycharmProjects/djangoProject2/venv/lib/python3.9/site-packages/django/core/handlers/exception.py", line 55, in inner
    response = get_response(request)
  File "/Users/yasinalbayrak/PycharmProjects/djangoProject2/venv/lib/python3.9/site-packages/django/core/handlers/base.py", line 197, in _get_response
    response = wrapped_callback(request, *callback_args, **callback_kwargs)
TypeError: news_detail() got an unexpected keyword argument 'news_id'
/Users/yasinalbayrak/PycharmProjects/djangoProject2/russianNews/views.py changed, reloading.
Watching for file changes with StatReloader
Internal Server Error: /news/1/
Traceback (most recent call last):
  File "/Users/yasinalbayrak/PycharmProjects/djangoProject2/venv/lib/python3.9/site-packages/django/core/handlers/exception.py", line 55, in inner
    response = get_response(request)
  File "/Users/yasinalbayrak/PycharmProjects/djangoProject2/venv/lib/python3.9/site-packages/django/core/handlers/base.py", line 197, in _get_response
    response = wrapped_callback(request, *callback_args, **callback_kwargs)
TypeError: news_detail() got an unexpected keyword argument 'news_id'
/Users/yasinalbayrak/PycharmProjects/djangoProject2/djangoProject2/urls.py changed, reloading.
Watching for file changes with StatReloader
/Users/yasinalbayrak/PycharmProjects/djangoProject2/djangoProject2/urls.py changed, reloading.
Watching for file changes with StatReloader
/Users/yasinalbayrak/PycharmProjects/djangoProject2/russianNews/views.py changed, reloading.
Watching for file changes with StatReloader
/Users/yasinalbayrak/PycharmProjects/djangoProject2/russianNews/views.py changed, reloading.
Watching for file changes with StatReloader
/Users/yasinalbayrak/PycharmProjects/djangoProject2/russianNews/views.py changed, reloading.
Watching for file changes with StatReloader
/Users/yasinalbayrak/PycharmProjects/djangoProject2/russianNews/views.py changed, reloading.
Watching for file changes with StatReloader
/Users/yasinalbayrak/PycharmProjects/djangoProject2/russianNews/views.py changed, reloading.
Watching for file changes with StatReloader
/Users/yasinalbayrak/PycharmProjects/djangoProject2/russianNews/views.py changed, reloading.
Watching for file changes with StatReloader
Unauthorized: /success/
Not Found: /static/rest_framework/css/bootstrap.min.css
Not Found: /static/rest_framework/css/bootstrap-tweaks.css
Not Found: /static/rest_framework/css/prettify.css
Not Found: /static/rest_framework/css/default.css
Not Found: /static/rest_framework/js/csrf.js
Not Found: /static/rest_framework/js/bootstrap.min.js
Not Found: /static/rest_framework/js/jquery-3.5.1.min.js
Not Found: /static/rest_framework/js/prettify-min.js
Not Found: /static/rest_framework/js/ajax-form.js
Not Found: /static/rest_framework/js/default.js
Not Found: /news_list/
/Users/yasinalbayrak/PycharmProjects/djangoProject2/auth_user/views.py changed, reloading.
Watching for file changes with StatReloader
Not Found: /login/news_list.html
/Users/yasinalbayrak/PycharmProjects/djangoProject2/auth_user/views.py changed, reloading.
Watching for file changes with StatReloader
/Users/yasinalbayrak/PycharmProjects/djangoProject2/auth_user/views.py changed, reloading.
Watching for file changes with StatReloader
/Users/yasinalbayrak/PycharmProjects/djangoProject2/djangoProject2/urls.py changed, reloading.
Watching for file changes with StatReloader
/Users/yasinalbayrak/PycharmProjects/djangoProject2/djangoProject2/urls.py changed, reloading.
Watching for file changes with StatReloader
/Users/yasinalbayrak/PycharmProjects/djangoProject2/russianNews/views.py changed, reloading.
Watching for file changes with StatReloader
/Users/yasinalbayrak/PycharmProjects/djangoProject2/russianNews/views.py changed, reloading.
Watching for file changes with StatReloader
/Users/yasinalbayrak/PycharmProjects/djangoProject2/russianNews/views.py changed, reloading.
Watching for file changes with StatReloader
/Users/yasinalbayrak/PycharmProjects/djangoProject2/russianNews/views.py changed, reloading.
Watching for file changes with StatReloader
Not Found: /manage_users/
Not Found: /accounts/login/
Not Found: /accounts/login/
Not Found: /accounts/login
Not Found: /accounts/login/
/Users/yasinalbayrak/PycharmProjects/djangoProject2/russianNews/views.py changed, reloading.
Watching for file changes with StatReloader
/Users/yasinalbayrak/PycharmProjects/djangoProject2/russianNews/views.py changed, reloading.
Watching for file changes with StatReloader
/Users/yasinalbayrak/PycharmProjects/djangoProject2/russianNews/views.py changed, reloading.
Watching for file changes with StatReloader
/Users/yasinalbayrak/PycharmProjects/djangoProject2/russianNews/views.py changed, reloading.
Watching for file changes with StatReloader
Registration failed: Username silaozinan already exists
Registration failed: Username new already exists
/Users/yasinalbayrak/PycharmProjects/djangoProject2/auth_user/views.py changed, reloading.
Watching for file changes with StatReloader
/Users/yasinalbayrak/PycharmProjects/djangoProject2/djangoProject2/urls.py changed, reloading.
Watching for file changes with StatReloader
/Users/yasinalbayrak/PycharmProjects/djangoProject2/russianNews/views.py changed, reloading.
Watching for file changes with StatReloader
Not Found: /accounts/login/
/Users/yasinalbayrak/PycharmProjects/djangoProject2/russianNews/views.py changed, reloading.
Watching for file changes with StatReloader
/Users/yasinalbayrak/PycharmProjects/djangoProject2/russianNews/views.py changed, reloading.
Watching for file changes with StatReloader
/Users/yasinalbayrak/PycharmProjects/djangoProject2/russianNews/views.py changed, reloading.
Watching for file changes with StatReloader
/Users/yasinalbayrak/PycharmProjects/djangoProject2/russianNews/views.py changed, reloading.
Watching for file changes with StatReloader
/Users/yasinalbayrak/PycharmProjects/djangoProject2/russianNews/views.py changed, reloading.
Watching for file changes with StatReloader
Not Found: /accounts/login/
Not Found: /accounts/login/
Not Found: /accounts/login/
Not Found: /accounts/login/
Not Found: /accounts/login/
/Users/yasinalbayrak/PycharmProjects/djangoProject2/russianNews/views.py changed, reloading.
Watching for file changes with StatReloader
Watching for file changes with StatReloader
/Users/yasinalbayrak/PycharmProjects/djangoProject2/russianNews/views.py changed, reloading.
Watching for file changes with StatReloader
/Users/yasinalbayrak/PycharmProjects/djangoProject2/russianNews/views.py changed, reloading.
Watching for file changes with StatReloader
Internal Server Error: /news/
Traceback (most recent call last):
  File "/Users/yasinalbayrak/PycharmProjects/djangoProject2/venv/lib/python3.9/site-packages/django/core/handlers/exception.py", line 55, in inner
    response = get_response(request)
  File "/Users/yasinalbayrak/PycharmProjects/djangoProject2/venv/lib/python3.9/site-packages/django/core/handlers/base.py", line 197, in _get_response
    response = wrapped_callback(request, *callback_args, **callback_kwargs)
  File "/Users/yasinalbayrak/PycharmProjects/djangoProject2/russianNews/views.py", line 29, in news_list
    fetch_news()
  File "/Users/yasinalbayrak/PycharmProjects/djangoProject2/russianNews/views.py", line 61, in fetch_news
    title_en = translator.translate(title_ru, src='ru', dest='en').text
  File "/Users/yasinalbayrak/PycharmProjects/djangoProject2/venv/lib/python3.9/site-packages/googletrans/client.py", line 194, in translate
    data, response = self._translate(text, dest, src)
  File "/Users/yasinalbayrak/PycharmProjects/djangoProject2/venv/lib/python3.9/site-packages/googletrans/client.py", line 120, in _translate
    r = self.client.post(url, params=params, data=data)
  File "/Users/yasinalbayrak/PycharmProjects/djangoProject2/venv/lib/python3.9/site-packages/httpx/_client.py", line 824, in post
    return self.request(
  File "/Users/yasinalbayrak/PycharmProjects/djangoProject2/venv/lib/python3.9/site-packages/httpx/_client.py", line 600, in request
    return self.send(
  File "/Users/yasinalbayrak/PycharmProjects/djangoProject2/venv/lib/python3.9/site-packages/httpx/_client.py", line 620, in send
    response = self.send_handling_redirects(
  File "/Users/yasinalbayrak/PycharmProjects/djangoProject2/venv/lib/python3.9/site-packages/httpx/_client.py", line 647, in send_handling_redirects
    response = self.send_handling_auth(
  File "/Users/yasinalbayrak/PycharmProjects/djangoProject2/venv/lib/python3.9/site-packages/httpx/_client.py", line 684, in send_handling_auth
    response = self.send_single_request(request, timeout)
  File "/Users/yasinalbayrak/PycharmProjects/djangoProject2/venv/lib/python3.9/site-packages/httpx/_client.py", line 714, in send_single_request
    ) = transport.request(
  File "/Users/yasinalbayrak/PycharmProjects/djangoProject2/venv/lib/python3.9/site-packages/httpcore/_sync/connection_pool.py", line 152, in request
    response = connection.request(
  File "/Users/yasinalbayrak/PycharmProjects/djangoProject2/venv/lib/python3.9/site-packages/httpcore/_sync/connection.py", line 78, in request
    return self.connection.request(method, url, headers, stream, timeout)
  File "/Users/yasinalbayrak/PycharmProjects/djangoProject2/venv/lib/python3.9/site-packages/httpcore/_sync/http2.py", line 118, in request
    return h2_stream.request(method, url, headers, stream, timeout)
  File "/Users/yasinalbayrak/PycharmProjects/djangoProject2/venv/lib/python3.9/site-packages/httpcore/_sync/http2.py", line 292, in request
    status_code, headers = self.receive_response(timeout)
  File "/Users/yasinalbayrak/PycharmProjects/djangoProject2/venv/lib/python3.9/site-packages/httpcore/_sync/http2.py", line 344, in receive_response
    event = self.connection.wait_for_event(self.stream_id, timeout)
  File "/Users/yasinalbayrak/PycharmProjects/djangoProject2/venv/lib/python3.9/site-packages/httpcore/_sync/http2.py", line 197, in wait_for_event
    self.receive_events(timeout)
  File "/Users/yasinalbayrak/PycharmProjects/djangoProject2/venv/lib/python3.9/site-packages/httpcore/_sync/http2.py", line 204, in receive_events
    data = self.socket.read(self.READ_NUM_BYTES, timeout)
  File "/Users/yasinalbayrak/PycharmProjects/djangoProject2/venv/lib/python3.9/site-packages/httpcore/_backends/sync.py", line 62, in read
    return self.sock.recv(n)
  File "/Library/Developer/CommandLineTools/Library/Frameworks/Python3.framework/Versions/3.9/lib/python3.9/contextlib.py", line 135, in __exit__
    self.gen.throw(type, value, traceback)
  File "/Users/yasinalbayrak/PycharmProjects/djangoProject2/venv/lib/python3.9/site-packages/httpcore/_exceptions.py", line 12, in map_exceptions
    raise to_exc(exc) from None
httpcore._exceptions.ReadTimeout: The read operation timed out
/Users/yasinalbayrak/PycharmProjects/djangoProject2/russianNews/views.py changed, reloading.
Watching for file changes with StatReloader
/Users/yasinalbayrak/PycharmProjects/djangoProject2/russianNews/views.py changed, reloading.
Watching for file changes with StatReloader
Internal Server Error: /news/
Traceback (most recent call last):
  File "/Users/yasinalbayrak/PycharmProjects/djangoProject2/venv/lib/python3.9/site-packages/django/core/handlers/exception.py", line 55, in inner
    response = get_response(request)
  File "/Users/yasinalbayrak/PycharmProjects/djangoProject2/venv/lib/python3.9/site-packages/django/core/handlers/base.py", line 197, in _get_response
    response = wrapped_callback(request, *callback_args, **callback_kwargs)
  File "/Users/yasinalbayrak/PycharmProjects/djangoProject2/russianNews/views.py", line 29, in news_list
    fetch_news()
  File "/Users/yasinalbayrak/PycharmProjects/djangoProject2/russianNews/views.py", line 61, in fetch_news
    title_en = translator.translate(title_ru, src='ru', dest='en').text
  File "/Users/yasinalbayrak/PycharmProjects/djangoProject2/venv/lib/python3.9/site-packages/googletrans/client.py", line 194, in translate
    data, response = self._translate(text, dest, src)
  File "/Users/yasinalbayrak/PycharmProjects/djangoProject2/venv/lib/python3.9/site-packages/googletrans/client.py", line 120, in _translate
    r = self.client.post(url, params=params, data=data)
  File "/Users/yasinalbayrak/PycharmProjects/djangoProject2/venv/lib/python3.9/site-packages/httpx/_client.py", line 824, in post
    return self.request(
  File "/Users/yasinalbayrak/PycharmProjects/djangoProject2/venv/lib/python3.9/site-packages/httpx/_client.py", line 600, in request
    return self.send(
  File "/Users/yasinalbayrak/PycharmProjects/djangoProject2/venv/lib/python3.9/site-packages/httpx/_client.py", line 620, in send
    response = self.send_handling_redirects(
  File "/Users/yasinalbayrak/PycharmProjects/djangoProject2/venv/lib/python3.9/site-packages/httpx/_client.py", line 647, in send_handling_redirects
    response = self.send_handling_auth(
  File "/Users/yasinalbayrak/PycharmProjects/djangoProject2/venv/lib/python3.9/site-packages/httpx/_client.py", line 684, in send_handling_auth
    response = self.send_single_request(request, timeout)
  File "/Users/yasinalbayrak/PycharmProjects/djangoProject2/venv/lib/python3.9/site-packages/httpx/_client.py", line 714, in send_single_request
    ) = transport.request(
  File "/Users/yasinalbayrak/PycharmProjects/djangoProject2/venv/lib/python3.9/site-packages/httpcore/_sync/connection_pool.py", line 152, in request
    response = connection.request(
  File "/Users/yasinalbayrak/PycharmProjects/djangoProject2/venv/lib/python3.9/site-packages/httpcore/_sync/connection.py", line 78, in request
    return self.connection.request(method, url, headers, stream, timeout)
  File "/Users/yasinalbayrak/PycharmProjects/djangoProject2/venv/lib/python3.9/site-packages/httpcore/_sync/http2.py", line 118, in request
    return h2_stream.request(method, url, headers, stream, timeout)
  File "/Users/yasinalbayrak/PycharmProjects/djangoProject2/venv/lib/python3.9/site-packages/httpcore/_sync/http2.py", line 292, in request
    status_code, headers = self.receive_response(timeout)
  File "/Users/yasinalbayrak/PycharmProjects/djangoProject2/venv/lib/python3.9/site-packages/httpcore/_sync/http2.py", line 344, in receive_response
    event = self.connection.wait_for_event(self.stream_id, timeout)
  File "/Users/yasinalbayrak/PycharmProjects/djangoProject2/venv/lib/python3.9/site-packages/httpcore/_sync/http2.py", line 197, in wait_for_event
    self.receive_events(timeout)
  File "/Users/yasinalbayrak/PycharmProjects/djangoProject2/venv/lib/python3.9/site-packages/httpcore/_sync/http2.py", line 204, in receive_events
    data = self.socket.read(self.READ_NUM_BYTES, timeout)
  File "/Users/yasinalbayrak/PycharmProjects/djangoProject2/venv/lib/python3.9/site-packages/httpcore/_backends/sync.py", line 62, in read
    return self.sock.recv(n)
  File "/Library/Developer/CommandLineTools/Library/Frameworks/Python3.framework/Versions/3.9/lib/python3.9/contextlib.py", line 135, in __exit__
    self.gen.throw(type, value, traceback)
  File "/Users/yasinalbayrak/PycharmProjects/djangoProject2/venv/lib/python3.9/site-packages/httpcore/_exceptions.py", line 12, in map_exceptions
    raise to_exc(exc) from None
httpcore._exceptions.ReadTimeout: The read operation timed out
/Users/yasinalbayrak/PycharmProjects/djangoProject2/russianNews/views.py changed, reloading.
Watching for file changes with StatReloader
/Users/yasinalbayrak/PycharmProjects/djangoProject2/russianNews/views.py changed, reloading.
Watching for file changes with StatReloader
/Users/yasinalbayrak/PycharmProjects/djangoProject2/russianNews/views.py changed, reloading.
Watching for file changes with StatReloader
Internal Server Error: /news/
Traceback (most recent call last):
  File "/Users/yasinalbayrak/PycharmProjects/djangoProject2/venv/lib/python3.9/site-packages/django/core/handlers/exception.py", line 55, in inner
    response = get_response(request)
  File "/Users/yasinalbayrak/PycharmProjects/djangoProject2/venv/lib/python3.9/site-packages/django/core/handlers/base.py", line 197, in _get_response
    response = wrapped_callback(request, *callback_args, **callback_kwargs)
  File "/Users/yasinalbayrak/PycharmProjects/djangoProject2/russianNews/views.py", line 45, in news_list
    return render(request, 'news_list.html', {'news_items': news_items, 'search_query': search_query})
  File "/Users/yasinalbayrak/PycharmProjects/djangoProject2/venv/lib/python3.9/site-packages/django/shortcuts.py", line 24, in render
    content = loader.render_to_string(template_name, context, request, using=using)
  File "/Users/yasinalbayrak/PycharmProjects/djangoProject2/venv/lib/python3.9/site-packages/django/template/loader.py", line 62, in render_to_string
    return template.render(context, request)
  File "/Users/yasinalbayrak/PycharmProjects/djangoProject2/venv/lib/python3.9/site-packages/django/template/backends/django.py", line 61, in render
    return self.template.render(context)
  File "/Users/yasinalbayrak/PycharmProjects/djangoProject2/venv/lib/python3.9/site-packages/django/template/base.py", line 175, in render
    return self._render(context)
  File "/Users/yasinalbayrak/PycharmProjects/djangoProject2/venv/lib/python3.9/site-packages/django/template/base.py", line 167, in _render
    return self.nodelist.render(context)
  File "/Users/yasinalbayrak/PycharmProjects/djangoProject2/venv/lib/python3.9/site-packages/django/template/base.py", line 1005, in render
    return SafeString("".join([node.render_annotated(context) for node in self]))
  File "/Users/yasinalbayrak/PycharmProjects/djangoProject2/venv/lib/python3.9/site-packages/django/template/base.py", line 1005, in <listcomp>
    return SafeString("".join([node.render_annotated(context) for node in self]))
  File "/Users/yasinalbayrak/PycharmProjects/djangoProject2/venv/lib/python3.9/site-packages/django/template/base.py", line 966, in render_annotated
    return self.render(context)
  File "/Users/yasinalbayrak/PycharmProjects/djangoProject2/venv/lib/python3.9/site-packages/django/template/defaulttags.py", line 471, in render
    url = reverse(view_name, args=args, kwargs=kwargs, current_app=current_app)
  File "/Users/yasinalbayrak/PycharmProjects/djangoProject2/venv/lib/python3.9/site-packages/django/urls/base.py", line 88, in reverse
    return resolver._reverse_with_prefix(view, prefix, *args, **kwargs)
  File "/Users/yasinalbayrak/PycharmProjects/djangoProject2/venv/lib/python3.9/site-packages/django/urls/resolvers.py", line 828, in _reverse_with_prefix
    raise NoReverseMatch(msg)
django.urls.exceptions.NoReverseMatch: Reverse for 'url_news_search' not found. 'url_news_search' is not a valid view function or pattern name.
Internal Server Error: /news/
Traceback (most recent call last):
  File "/Users/yasinalbayrak/PycharmProjects/djangoProject2/venv/lib/python3.9/site-packages/django/core/handlers/exception.py", line 55, in inner
    response = get_response(request)
  File "/Users/yasinalbayrak/PycharmProjects/djangoProject2/venv/lib/python3.9/site-packages/django/core/handlers/base.py", line 197, in _get_response
    response = wrapped_callback(request, *callback_args, **callback_kwargs)
  File "/Users/yasinalbayrak/PycharmProjects/djangoProject2/russianNews/views.py", line 45, in news_list
    return render(request, 'news_list.html', {'news_items': news_items, 'search_query': search_query})
  File "/Users/yasinalbayrak/PycharmProjects/djangoProject2/venv/lib/python3.9/site-packages/django/shortcuts.py", line 24, in render
    content = loader.render_to_string(template_name, context, request, using=using)
  File "/Users/yasinalbayrak/PycharmProjects/djangoProject2/venv/lib/python3.9/site-packages/django/template/loader.py", line 62, in render_to_string
    return template.render(context, request)
  File "/Users/yasinalbayrak/PycharmProjects/djangoProject2/venv/lib/python3.9/site-packages/django/template/backends/django.py", line 61, in render
    return self.template.render(context)
  File "/Users/yasinalbayrak/PycharmProjects/djangoProject2/venv/lib/python3.9/site-packages/django/template/base.py", line 175, in render
    return self._render(context)
  File "/Users/yasinalbayrak/PycharmProjects/djangoProject2/venv/lib/python3.9/site-packages/django/template/base.py", line 167, in _render
    return self.nodelist.render(context)
  File "/Users/yasinalbayrak/PycharmProjects/djangoProject2/venv/lib/python3.9/site-packages/django/template/base.py", line 1005, in render
    return SafeString("".join([node.render_annotated(context) for node in self]))
  File "/Users/yasinalbayrak/PycharmProjects/djangoProject2/venv/lib/python3.9/site-packages/django/template/base.py", line 1005, in <listcomp>
    return SafeString("".join([node.render_annotated(context) for node in self]))
  File "/Users/yasinalbayrak/PycharmProjects/djangoProject2/venv/lib/python3.9/site-packages/django/template/base.py", line 966, in render_annotated
    return self.render(context)
  File "/Users/yasinalbayrak/PycharmProjects/djangoProject2/venv/lib/python3.9/site-packages/django/template/defaulttags.py", line 471, in render
    url = reverse(view_name, args=args, kwargs=kwargs, current_app=current_app)
  File "/Users/yasinalbayrak/PycharmProjects/djangoProject2/venv/lib/python3.9/site-packages/django/urls/base.py", line 88, in reverse
    return resolver._reverse_with_prefix(view, prefix, *args, **kwargs)
  File "/Users/yasinalbayrak/PycharmProjects/djangoProject2/venv/lib/python3.9/site-packages/django/urls/resolvers.py", line 828, in _reverse_with_prefix
    raise NoReverseMatch(msg)
django.urls.exceptions.NoReverseMatch: Reverse for 'url_news_search' not found. 'url_news_search' is not a valid view function or pattern name.
/Users/yasinalbayrak/PycharmProjects/djangoProject2/russianNews/views.py changed, reloading.
Watching for file changes with StatReloader
Internal Server Error: /news/
Traceback (most recent call last):
  File "/Users/yasinalbayrak/PycharmProjects/djangoProject2/venv/lib/python3.9/site-packages/django/core/handlers/exception.py", line 55, in inner
    response = get_response(request)
  File "/Users/yasinalbayrak/PycharmProjects/djangoProject2/venv/lib/python3.9/site-packages/django/core/handlers/base.py", line 197, in _get_response
    response = wrapped_callback(request, *callback_args, **callback_kwargs)
  File "/Users/yasinalbayrak/PycharmProjects/djangoProject2/russianNews/views.py", line 46, in news_list
    return render(request, 'news_list.html', {'news_items': news_items, 'search_query': search_query})
  File "/Users/yasinalbayrak/PycharmProjects/djangoProject2/venv/lib/python3.9/site-packages/django/shortcuts.py", line 24, in render
    content = loader.render_to_string(template_name, context, request, using=using)
  File "/Users/yasinalbayrak/PycharmProjects/djangoProject2/venv/lib/python3.9/site-packages/django/template/loader.py", line 62, in render_to_string
    return template.render(context, request)
  File "/Users/yasinalbayrak/PycharmProjects/djangoProject2/venv/lib/python3.9/site-packages/django/template/backends/django.py", line 61, in render
    return self.template.render(context)
  File "/Users/yasinalbayrak/PycharmProjects/djangoProject2/venv/lib/python3.9/site-packages/django/template/base.py", line 175, in render
    return self._render(context)
  File "/Users/yasinalbayrak/PycharmProjects/djangoProject2/venv/lib/python3.9/site-packages/django/template/base.py", line 167, in _render
    return self.nodelist.render(context)
  File "/Users/yasinalbayrak/PycharmProjects/djangoProject2/venv/lib/python3.9/site-packages/django/template/base.py", line 1005, in render
    return SafeString("".join([node.render_annotated(context) for node in self]))
  File "/Users/yasinalbayrak/PycharmProjects/djangoProject2/venv/lib/python3.9/site-packages/django/template/base.py", line 1005, in <listcomp>
    return SafeString("".join([node.render_annotated(context) for node in self]))
  File "/Users/yasinalbayrak/PycharmProjects/djangoProject2/venv/lib/python3.9/site-packages/django/template/base.py", line 966, in render_annotated
    return self.render(context)
  File "/Users/yasinalbayrak/PycharmProjects/djangoProject2/venv/lib/python3.9/site-packages/django/template/defaulttags.py", line 471, in render
    url = reverse(view_name, args=args, kwargs=kwargs, current_app=current_app)
  File "/Users/yasinalbayrak/PycharmProjects/djangoProject2/venv/lib/python3.9/site-packages/django/urls/base.py", line 88, in reverse
    return resolver._reverse_with_prefix(view, prefix, *args, **kwargs)
  File "/Users/yasinalbayrak/PycharmProjects/djangoProject2/venv/lib/python3.9/site-packages/django/urls/resolvers.py", line 828, in _reverse_with_prefix
    raise NoReverseMatch(msg)
django.urls.exceptions.NoReverseMatch: Reverse for 'url_news_search' not found. 'url_news_search' is not a valid view function or pattern name.
/Users/yasinalbayrak/PycharmProjects/djangoProject2/russianNews/views.py changed, reloading.
Watching for file changes with StatReloader
/Users/yasinalbayrak/PycharmProjects/djangoProject2/russianNews/views.py changed, reloading.
Watching for file changes with StatReloader
/Users/yasinalbayrak/PycharmProjects/djangoProject2/russianNews/views.py changed, reloading.
Watching for file changes with StatReloader
/Users/yasinalbayrak/PycharmProjects/djangoProject2/russianNews/views.py changed, reloading.
Watching for file changes with StatReloader
Internal Server Error: /news/
Traceback (most recent call last):
  File "/Users/yasinalbayrak/PycharmProjects/djangoProject2/venv/lib/python3.9/site-packages/django/core/handlers/exception.py", line 55, in inner
    response = get_response(request)
  File "/Users/yasinalbayrak/PycharmProjects/djangoProject2/venv/lib/python3.9/site-packages/django/core/handlers/base.py", line 197, in _get_response
    response = wrapped_callback(request, *callback_args, **callback_kwargs)
  File "/Users/yasinalbayrak/PycharmProjects/djangoProject2/russianNews/views.py", line 46, in news_list
    return render(request, 'news_list.html', {'news_items': news_items, 'search_query': search_query})
  File "/Users/yasinalbayrak/PycharmProjects/djangoProject2/venv/lib/python3.9/site-packages/django/shortcuts.py", line 24, in render
    content = loader.render_to_string(template_name, context, request, using=using)
  File "/Users/yasinalbayrak/PycharmProjects/djangoProject2/venv/lib/python3.9/site-packages/django/template/loader.py", line 62, in render_to_string
    return template.render(context, request)
  File "/Users/yasinalbayrak/PycharmProjects/djangoProject2/venv/lib/python3.9/site-packages/django/template/backends/django.py", line 61, in render
    return self.template.render(context)
  File "/Users/yasinalbayrak/PycharmProjects/djangoProject2/venv/lib/python3.9/site-packages/django/template/base.py", line 175, in render
    return self._render(context)
  File "/Users/yasinalbayrak/PycharmProjects/djangoProject2/venv/lib/python3.9/site-packages/django/template/base.py", line 167, in _render
    return self.nodelist.render(context)
  File "/Users/yasinalbayrak/PycharmProjects/djangoProject2/venv/lib/python3.9/site-packages/django/template/base.py", line 1005, in render
    return SafeString("".join([node.render_annotated(context) for node in self]))
  File "/Users/yasinalbayrak/PycharmProjects/djangoProject2/venv/lib/python3.9/site-packages/django/template/base.py", line 1005, in <listcomp>
    return SafeString("".join([node.render_annotated(context) for node in self]))
  File "/Users/yasinalbayrak/PycharmProjects/djangoProject2/venv/lib/python3.9/site-packages/django/template/base.py", line 966, in render_annotated
    return self.render(context)
  File "/Users/yasinalbayrak/PycharmProjects/djangoProject2/venv/lib/python3.9/site-packages/django/template/defaulttags.py", line 471, in render
    url = reverse(view_name, args=args, kwargs=kwargs, current_app=current_app)
  File "/Users/yasinalbayrak/PycharmProjects/djangoProject2/venv/lib/python3.9/site-packages/django/urls/base.py", line 88, in reverse
    return resolver._reverse_with_prefix(view, prefix, *args, **kwargs)
  File "/Users/yasinalbayrak/PycharmProjects/djangoProject2/venv/lib/python3.9/site-packages/django/urls/resolvers.py", line 828, in _reverse_with_prefix
    raise NoReverseMatch(msg)
django.urls.exceptions.NoReverseMatch: Reverse for 'url_news_search' not found. 'url_news_search' is not a valid view function or pattern name.
Internal Server Error: /news/
Traceback (most recent call last):
  File "/Users/yasinalbayrak/PycharmProjects/djangoProject2/venv/lib/python3.9/site-packages/django/core/handlers/exception.py", line 55, in inner
    response = get_response(request)
  File "/Users/yasinalbayrak/PycharmProjects/djangoProject2/venv/lib/python3.9/site-packages/django/core/handlers/base.py", line 197, in _get_response
    response = wrapped_callback(request, *callback_args, **callback_kwargs)
  File "/Users/yasinalbayrak/PycharmProjects/djangoProject2/russianNews/views.py", line 46, in news_list
    return render(request, 'news_list.html', {'news_items': news_items, 'search_query': search_query})
  File "/Users/yasinalbayrak/PycharmProjects/djangoProject2/venv/lib/python3.9/site-packages/django/shortcuts.py", line 24, in render
    content = loader.render_to_string(template_name, context, request, using=using)
  File "/Users/yasinalbayrak/PycharmProjects/djangoProject2/venv/lib/python3.9/site-packages/django/template/loader.py", line 62, in render_to_string
    return template.render(context, request)
  File "/Users/yasinalbayrak/PycharmProjects/djangoProject2/venv/lib/python3.9/site-packages/django/template/backends/django.py", line 61, in render
    return self.template.render(context)
  File "/Users/yasinalbayrak/PycharmProjects/djangoProject2/venv/lib/python3.9/site-packages/django/template/base.py", line 175, in render
    return self._render(context)
  File "/Users/yasinalbayrak/PycharmProjects/djangoProject2/venv/lib/python3.9/site-packages/django/template/base.py", line 167, in _render
    return self.nodelist.render(context)
  File "/Users/yasinalbayrak/PycharmProjects/djangoProject2/venv/lib/python3.9/site-packages/django/template/base.py", line 1005, in render
    return SafeString("".join([node.render_annotated(context) for node in self]))
  File "/Users/yasinalbayrak/PycharmProjects/djangoProject2/venv/lib/python3.9/site-packages/django/template/base.py", line 1005, in <listcomp>
    return SafeString("".join([node.render_annotated(context) for node in self]))
  File "/Users/yasinalbayrak/PycharmProjects/djangoProject2/venv/lib/python3.9/site-packages/django/template/base.py", line 966, in render_annotated
    return self.render(context)
  File "/Users/yasinalbayrak/PycharmProjects/djangoProject2/venv/lib/python3.9/site-packages/django/template/defaulttags.py", line 471, in render
    url = reverse(view_name, args=args, kwargs=kwargs, current_app=current_app)
  File "/Users/yasinalbayrak/PycharmProjects/djangoProject2/venv/lib/python3.9/site-packages/django/urls/base.py", line 88, in reverse
    return resolver._reverse_with_prefix(view, prefix, *args, **kwargs)
  File "/Users/yasinalbayrak/PycharmProjects/djangoProject2/venv/lib/python3.9/site-packages/django/urls/resolvers.py", line 828, in _reverse_with_prefix
    raise NoReverseMatch(msg)
django.urls.exceptions.NoReverseMatch: Reverse for 'url_news_search' not found. 'url_news_search' is not a valid view function or pattern name.
/Users/yasinalbayrak/PycharmProjects/djangoProject2/djangoProject2/urls.py changed, reloading.
Watching for file changes with StatReloader
Internal Server Error: /url_news_search
Traceback (most recent call last):
  File "/Users/yasinalbayrak/PycharmProjects/djangoProject2/venv/lib/python3.9/site-packages/django/core/handlers/exception.py", line 55, in inner
    response = get_response(request)
  File "/Users/yasinalbayrak/PycharmProjects/djangoProject2/venv/lib/python3.9/site-packages/django/core/handlers/base.py", line 197, in _get_response
    response = wrapped_callback(request, *callback_args, **callback_kwargs)
  File "/Users/yasinalbayrak/PycharmProjects/djangoProject2/russianNews/views.py", line 199, in url_news_search
    response = requests.get(url)
  File "/Users/yasinalbayrak/PycharmProjects/djangoProject2/venv/lib/python3.9/site-packages/requests/api.py", line 73, in get
    return request("get", url, params=params, **kwargs)
  File "/Users/yasinalbayrak/PycharmProjects/djangoProject2/venv/lib/python3.9/site-packages/requests/api.py", line 59, in request
    return session.request(method=method, url=url, **kwargs)
  File "/Users/yasinalbayrak/PycharmProjects/djangoProject2/venv/lib/python3.9/site-packages/requests/sessions.py", line 575, in request
    prep = self.prepare_request(req)
  File "/Users/yasinalbayrak/PycharmProjects/djangoProject2/venv/lib/python3.9/site-packages/requests/sessions.py", line 486, in prepare_request
    p.prepare(
  File "/Users/yasinalbayrak/PycharmProjects/djangoProject2/venv/lib/python3.9/site-packages/requests/models.py", line 368, in prepare
    self.prepare_url(url, params)
  File "/Users/yasinalbayrak/PycharmProjects/djangoProject2/venv/lib/python3.9/site-packages/requests/models.py", line 439, in prepare_url
    raise MissingSchema(
requests.exceptions.MissingSchema: Invalid URL 'asda': No scheme supplied. Perhaps you meant https://asda?
/Users/yasinalbayrak/PycharmProjects/djangoProject2/russianNews/views.py changed, reloading.
Watching for file changes with StatReloader
/Users/yasinalbayrak/PycharmProjects/djangoProject2/russianNews/views.py changed, reloading.
Watching for file changes with StatReloader
/Users/yasinalbayrak/PycharmProjects/djangoProject2/djangoProject2/urls.py changed, reloading.
Watching for file changes with StatReloader
/Users/yasinalbayrak/PycharmProjects/djangoProject2/djangoProject2/urls.py changed, reloading.
Watching for file changes with StatReloader
/Users/yasinalbayrak/PycharmProjects/djangoProject2/djangoProject2/urls.py changed, reloading.
Watching for file changes with StatReloader
Not Found: /url_news_search
Not Found: /url_news_search
/Users/yasinalbayrak/PycharmProjects/djangoProject2/russianNews/views.py changed, reloading.
Watching for file changes with StatReloader
/Users/yasinalbayrak/PycharmProjects/djangoProject2/russianNews/views.py changed, reloading.
Watching for file changes with StatReloader
/Users/yasinalbayrak/PycharmProjects/djangoProject2/russianNews/views.py changed, reloading.
Watching for file changes with StatReloader
/Users/yasinalbayrak/PycharmProjects/djangoProject2/djangoProject2/urls.py changed, reloading.
Watching for file changes with StatReloader
Watching for file changes with StatReloader
/Users/yasinalbayrak/PycharmProjects/djangoProject2/russianNews/views.py changed, reloading.
Watching for file changes with StatReloader
Internal Server Error: /api/v1/executeCommand
Internal Server Error: /api/v1/executeCommand
Internal Server Error: /api/v1/executeCommand
Internal Server Error: /api/v1/executeCommand
Internal Server Error: /api/v1/executeCommand
Internal Server Error: /api/v1/executeCommand
Internal Server Error: /api/v1/executeCommand
Internal Server Error: /api/v1/executeCommand
Internal Server Error: /api/v1/executeCommand
Internal Server Error: /api/v1/executeCommand
Internal Server Error: /api/v1/executeCommand
Internal Server Error: /api/v1/executeCommand
Internal Server Error: /api/v1/executeCommand
Internal Server Error: /api/v1/executeCommand
Internal Server Error: /api/v1/executeCommand
Internal Server Error: /api/v1/executeCommand
Internal Server Error: /api/v1/executeCommand
Internal Server Error: /api/v1/executeCommand
Internal Server Error: /api/v1/executeCommand
Internal Server Error: /api/v1/executeCommand
Internal Server Error: /api/v1/executeCommand
Internal Server Error: /api/v1/executeCommand
Internal Server Error: /api/v1/executeCommand
Internal Server Error: /api/v1/executeCommand
Internal Server Error: /api/v1/executeCommand
Internal Server Error: /api/v1/executeCommand
Internal Server Error: /api/v1/executeCommand
Internal Server Error: /api/v1/executeCommand
Internal Server Error: /api/v1/executeCommand
Internal Server Error: /api/v1/executeCommand
Internal Server Error: /api/v1/executeCommand
Internal Server Error: /api/v1/executeCommand
Internal Server Error: /api/v1/executeCommand
Internal Server Error: /api/v1/executeCommand
Internal Server Error: /api/v1/executeCommand
Internal Server Error: /api/v1/executeCommand
Internal Server Error: /api/v1/executeCommand
Internal Server Error: /api/v1/executeCommand
Internal Server Error: /api/v1/executeCommand
Internal Server Error: /api/v1/executeCommand
Internal Server Error: /api/v1/executeCommand
Internal Server Error: /api/v1/executeCommand
Internal Server Error: /api/v1/executeCommand
Internal Server Error: /api/v1/executeCommand
Internal Server Error: /api/v1/executeCommand
Internal Server Error: /api/v1/executeCommand
Internal Server Error: /api/v1/executeCommand
Internal Server Error: /api/v1/executeCommand
Internal Server Error: /api/v1/executeCommand
Internal Server Error: /api/v1/executeCommand
Internal Server Error: /api/v1/executeCommand
Internal Server Error: /api/v1/executeCommand
Internal Server Error: /api/v1/executeCommand
Internal Server Error: /api/v1/executeCommand
Internal Server Error: /api/v1/executeCommand
Internal Server Error: /api/v1/executeCommand
Internal Server Error: /api/v1/executeCommand
Internal Server Error: /api/v1/executeCommand
Internal Server Error: /api/v1/executeCommand
Internal Server Error: /api/v1/executeCommand
Internal Server Error: /api/v1/executeCommand
Internal Server Error: /api/v1/executeCommand
Internal Server Error: /api/v1/executeCommand
Internal Server Error: /api/v1/executeCommand
Internal Server Error: /api/v1/executeCommand
Internal Server Error: /api/v1/executeCommand
Internal Server Error: /api/v1/executeCommand
Internal Server Error: /api/v1/executeCommand
Internal Server Error: /api/v1/executeCommand
Internal Server Error: /api/v1/executeCommand
Internal Server Error: /api/v1/executeCommand
Internal Server Error: /api/v1/executeCommand
Internal Server Error: /api/v1/executeCommand
Internal Server Error: /api/v1/executeCommand
Internal Server Error: /api/v1/executeCommand
Internal Server Error: /api/v1/executeCommand
Internal Server Error: /api/v1/executeCommand
Internal Server Error: /api/v1/executeCommand
Internal Server Error: /api/v1/executeCommand
Internal Server Error: /api/v1/executeCommand
Internal Server Error: /api/v1/executeCommand
Internal Server Error: /api/v1/executeCommand
Internal Server Error: /api/v1/executeCommand
Internal Server Error: /api/v1/executeCommand
Internal Server Error: /api/v1/executeCommand
Internal Server Error: /api/v1/executeCommand
Internal Server Error: /api/v1/executeCommand
Internal Server Error: /api/v1/executeCommand
Internal Server Error: /api/v1/executeCommand
Internal Server Error: /api/v1/executeCommand
Internal Server Error: /api/v1/executeCommand
Internal Server Error: /api/v1/executeCommand
Internal Server Error: /api/v1/executeCommand
Internal Server Error: /api/v1/executeCommand
Internal Server Error: /api/v1/executeCommand
Internal Server Error: /api/v1/executeCommand
Internal Server Error: /api/v1/executeCommand
Internal Server Error: /api/v1/executeCommand
Internal Server Error: /api/v1/executeCommand
Internal Server Error: /api/v1/executeCommand
Internal Server Error: /api/v1/executeCommand
Internal Server Error: /api/v1/executeCommand
Internal Server Error: /api/v1/executeCommand
Internal Server Error: /api/v1/executeCommand
Internal Server Error: /api/v1/executeCommand
Internal Server Error: /api/v1/executeCommand
Internal Server Error: /api/v1/executeCommand
Internal Server Error: /api/v1/executeCommand
Internal Server Error: /api/v1/executeCommand
Internal Server Error: /api/v1/executeCommand
Internal Server Error: /api/v1/executeCommand
Internal Server Error: /api/v1/executeCommand
Internal Server Error: /api/v1/executeCommand
Internal Server Error: /api/v1/executeCommand
Internal Server Error: /api/v1/executeCommand
Internal Server Error: /api/v1/executeCommand
Internal Server Error: /api/v1/executeCommand
Internal Server Error: /api/v1/executeCommand
Internal Server Error: /api/v1/executeCommand
Internal Server Error: /api/v1/executeCommand
Internal Server Error: /api/v1/executeCommand
Internal Server Error: /api/v1/executeCommand
Internal Server Error: /api/v1/executeCommand
Internal Server Error: /api/v1/executeCommand
Internal Server Error: /api/v1/executeCommand
Internal Server Error: /api/v1/executeCommand
Internal Server Error: /api/v1/executeCommand
Internal Server Error: /api/v1/executeCommand
Internal Server Error: /api/v1/executeCommand
Internal Server Error: /api/v1/executeCommand
Internal Server Error: /api/v1/executeCommand
Internal Server Error: /api/v1/executeCommand
Internal Server Error: /api/v1/executeCommand
Internal Server Error: /api/v1/executeCommand
Internal Server Error: /api/v1/executeCommand
Internal Server Error: /api/v1/executeCommand
Internal Server Error: /api/v1/executeCommand
Internal Server Error: /api/v1/executeCommand
Internal Server Error: /api/v1/executeCommand
Internal Server Error: /api/v1/executeCommand
Internal Server Error: /api/v1/executeCommand
Internal Server Error: /api/v1/executeCommand
Internal Server Error: /api/v1/executeCommand
Internal Server Error: /api/v1/executeCommand
Internal Server Error: /api/v1/executeCommand
Internal Server Error: /api/v1/executeCommand
Internal Server Error: /api/v1/executeCommand
Internal Server Error: /api/v1/executeCommand
Internal Server Error: /api/v1/executeCommand
Internal Server Error: /api/v1/executeCommand
Internal Server Error: /api/v1/executeCommand
Internal Server Error: /api/v1/executeCommand
Internal Server Error: /api/v1/executeCommand
Internal Server Error: /api/v1/executeCommand
Internal Server Error: /api/v1/executeCommand
Internal Server Error: /api/v1/executeCommand
Internal Server Error: /api/v1/executeCommand
Internal Server Error: /api/v1/executeCommand
Internal Server Error: /api/v1/executeCommand
Internal Server Error: /news/
Traceback (most recent call last):
  File "/Users/yasinalbayrak/PycharmProjects/djangoProject2/venv/lib/python3.9/site-packages/django/core/handlers/exception.py", line 55, in inner
    response = get_response(request)
  File "/Users/yasinalbayrak/PycharmProjects/djangoProject2/venv/lib/python3.9/site-packages/django/core/handlers/base.py", line 197, in _get_response
    response = wrapped_callback(request, *callback_args, **callback_kwargs)
  File "/Users/yasinalbayrak/PycharmProjects/djangoProject2/russianNews/views.py", line 46, in news_list
    return render(request, 'news_list.html', {'news_items': news_items, 'search_query': search_query})
  File "/Users/yasinalbayrak/PycharmProjects/djangoProject2/venv/lib/python3.9/site-packages/django/shortcuts.py", line 24, in render
    content = loader.render_to_string(template_name, context, request, using=using)
  File "/Users/yasinalbayrak/PycharmProjects/djangoProject2/venv/lib/python3.9/site-packages/django/template/loader.py", line 62, in render_to_string
    return template.render(context, request)
  File "/Users/yasinalbayrak/PycharmProjects/djangoProject2/venv/lib/python3.9/site-packages/django/template/backends/django.py", line 61, in render
    return self.template.render(context)
  File "/Users/yasinalbayrak/PycharmProjects/djangoProject2/venv/lib/python3.9/site-packages/django/template/base.py", line 175, in render
    return self._render(context)
  File "/Users/yasinalbayrak/PycharmProjects/djangoProject2/venv/lib/python3.9/site-packages/django/template/base.py", line 167, in _render
    return self.nodelist.render(context)
  File "/Users/yasinalbayrak/PycharmProjects/djangoProject2/venv/lib/python3.9/site-packages/django/template/base.py", line 1005, in render
    return SafeString("".join([node.render_annotated(context) for node in self]))
  File "/Users/yasinalbayrak/PycharmProjects/djangoProject2/venv/lib/python3.9/site-packages/django/template/base.py", line 1005, in <listcomp>
    return SafeString("".join([node.render_annotated(context) for node in self]))
  File "/Users/yasinalbayrak/PycharmProjects/djangoProject2/venv/lib/python3.9/site-packages/django/template/base.py", line 966, in render_annotated
    return self.render(context)
  File "/Users/yasinalbayrak/PycharmProjects/djangoProject2/venv/lib/python3.9/site-packages/django/template/defaulttags.py", line 471, in render
    url = reverse(view_name, args=args, kwargs=kwargs, current_app=current_app)
  File "/Users/yasinalbayrak/PycharmProjects/djangoProject2/venv/lib/python3.9/site-packages/django/urls/base.py", line 88, in reverse
    return resolver._reverse_with_prefix(view, prefix, *args, **kwargs)
  File "/Users/yasinalbayrak/PycharmProjects/djangoProject2/venv/lib/python3.9/site-packages/django/urls/resolvers.py", line 828, in _reverse_with_prefix
    raise NoReverseMatch(msg)
django.urls.exceptions.NoReverseMatch: Reverse for 'your_second_search_url' not found. 'your_second_search_url' is not a valid view function or pattern name.
/Users/yasinalbayrak/PycharmProjects/djangoProject2/russianNews/views.py changed, reloading.
Watching for file changes with StatReloader
/Users/yasinalbayrak/PycharmProjects/djangoProject2/russianNews/views.py changed, reloading.
Watching for file changes with StatReloader
Watching for file changes with StatReloader
Watching for file changes with StatReloader
/Users/yasinalbayrak/PycharmProjects/djangoProject2/djangoProject2/urls.py changed, reloading.
Watching for file changes with StatReloader
/Users/yasinalbayrak/PycharmProjects/djangoProject2/russianNews/views.py changed, reloading.
Watching for file changes with StatReloader
/Users/yasinalbayrak/PycharmProjects/djangoProject2/djangoProject2/urls.py changed, reloading.
Watching for file changes with StatReloader
/Users/yasinalbayrak/PycharmProjects/djangoProject2/russianNews/views.py changed, reloading.
Watching for file changes with StatReloader
/Users/yasinalbayrak/PycharmProjects/djangoProject2/russianNews/forms.py changed, reloading.
Watching for file changes with StatReloader
/Users/yasinalbayrak/PycharmProjects/djangoProject2/russianNews/views.py changed, reloading.
Watching for file changes with StatReloader
/Users/yasinalbayrak/PycharmProjects/djangoProject2/russianNews/views.py changed, reloading.
Watching for file changes with StatReloader
Not Found: /get_image/
/Users/yasinalbayrak/PycharmProjects/djangoProject2/russianNews/views.py changed, reloading.
Watching for file changes with StatReloader
/Users/yasinalbayrak/PycharmProjects/djangoProject2/russianNews/views.py changed, reloading.
Watching for file changes with StatReloader
/Users/yasinalbayrak/PycharmProjects/djangoProject2/russianNews/views.py changed, reloading.
Watching for file changes with StatReloader
/Users/yasinalbayrak/PycharmProjects/djangoProject2/russianNews/views.py changed, reloading.
Watching for file changes with StatReloader
/Users/yasinalbayrak/PycharmProjects/djangoProject2/russianNews/views.py changed, reloading.
Watching for file changes with StatReloader
Internal Server Error: /news/156/
Traceback (most recent call last):
  File "/Users/yasinalbayrak/PycharmProjects/djangoProject2/venv/lib/python3.9/site-packages/django/core/handlers/exception.py", line 55, in inner
    response = get_response(request)
  File "/Users/yasinalbayrak/PycharmProjects/djangoProject2/venv/lib/python3.9/site-packages/django/core/handlers/base.py", line 197, in _get_response
    response = wrapped_callback(request, *callback_args, **callback_kwargs)
  File "/Users/yasinalbayrak/PycharmProjects/djangoProject2/venv/lib/python3.9/site-packages/django/contrib/auth/decorators.py", line 23, in _wrapper_view
    return view_func(request, *args, **kwargs)
  File "/Users/yasinalbayrak/PycharmProjects/djangoProject2/russianNews/views.py", line 160, in news_detail
    return render(request, 'news_detail.html', {'news_item': news_item, 'form': form})
  File "/Users/yasinalbayrak/PycharmProjects/djangoProject2/venv/lib/python3.9/site-packages/django/shortcuts.py", line 24, in render
    content = loader.render_to_string(template_name, context, request, using=using)
  File "/Users/yasinalbayrak/PycharmProjects/djangoProject2/venv/lib/python3.9/site-packages/django/template/loader.py", line 62, in render_to_string
    return template.render(context, request)
  File "/Users/yasinalbayrak/PycharmProjects/djangoProject2/venv/lib/python3.9/site-packages/django/template/backends/django.py", line 61, in render
    return self.template.render(context)
  File "/Users/yasinalbayrak/PycharmProjects/djangoProject2/venv/lib/python3.9/site-packages/django/template/base.py", line 175, in render
    return self._render(context)
  File "/Users/yasinalbayrak/PycharmProjects/djangoProject2/venv/lib/python3.9/site-packages/django/template/base.py", line 167, in _render
    return self.nodelist.render(context)
  File "/Users/yasinalbayrak/PycharmProjects/djangoProject2/venv/lib/python3.9/site-packages/django/template/base.py", line 1005, in render
    return SafeString("".join([node.render_annotated(context) for node in self]))
  File "/Users/yasinalbayrak/PycharmProjects/djangoProject2/venv/lib/python3.9/site-packages/django/template/base.py", line 1005, in <listcomp>
    return SafeString("".join([node.render_annotated(context) for node in self]))
  File "/Users/yasinalbayrak/PycharmProjects/djangoProject2/venv/lib/python3.9/site-packages/django/template/base.py", line 966, in render_annotated
    return self.render(context)
  File "/Users/yasinalbayrak/PycharmProjects/djangoProject2/venv/lib/python3.9/site-packages/django/template/defaulttags.py", line 471, in render
    url = reverse(view_name, args=args, kwargs=kwargs, current_app=current_app)
  File "/Users/yasinalbayrak/PycharmProjects/djangoProject2/venv/lib/python3.9/site-packages/django/urls/base.py", line 88, in reverse
    return resolver._reverse_with_prefix(view, prefix, *args, **kwargs)
  File "/Users/yasinalbayrak/PycharmProjects/djangoProject2/venv/lib/python3.9/site-packages/django/urls/resolvers.py", line 828, in _reverse_with_prefix
    raise NoReverseMatch(msg)
django.urls.exceptions.NoReverseMatch: Reverse for 'get-image' not found. 'get-image' is not a valid view function or pattern name.
/Users/yasinalbayrak/PycharmProjects/djangoProject2/russianNews/views.py changed, reloading.
Watching for file changes with StatReloader
/Users/yasinalbayrak/PycharmProjects/djangoProject2/russianNews/views.py changed, reloading.
Watching for file changes with StatReloader
Internal Server Error: /get-image/
Traceback (most recent call last):
  File "/Users/yasinalbayrak/PycharmProjects/djangoProject2/venv/lib/python3.9/site-packages/urllib3/connection.py", line 203, in _new_conn
    sock = connection.create_connection(
  File "/Users/yasinalbayrak/PycharmProjects/djangoProject2/venv/lib/python3.9/site-packages/urllib3/util/connection.py", line 85, in create_connection
    raise err
  File "/Users/yasinalbayrak/PycharmProjects/djangoProject2/venv/lib/python3.9/site-packages/urllib3/util/connection.py", line 73, in create_connection
    sock.connect(sa)
ConnectionRefusedError: [Errno 61] Connection refused

The above exception was the direct cause of the following exception:

Traceback (most recent call last):
  File "/Users/yasinalbayrak/PycharmProjects/djangoProject2/venv/lib/python3.9/site-packages/urllib3/connectionpool.py", line 790, in urlopen
    response = self._make_request(
  File "/Users/yasinalbayrak/PycharmProjects/djangoProject2/venv/lib/python3.9/site-packages/urllib3/connectionpool.py", line 496, in _make_request
    conn.request(
  File "/Users/yasinalbayrak/PycharmProjects/djangoProject2/venv/lib/python3.9/site-packages/urllib3/connection.py", line 395, in request
    self.endheaders()
  File "/Library/Developer/CommandLineTools/Library/Frameworks/Python3.framework/Versions/3.9/lib/python3.9/http/client.py", line 1252, in endheaders
    self._send_output(message_body, encode_chunked=encode_chunked)
  File "/Library/Developer/CommandLineTools/Library/Frameworks/Python3.framework/Versions/3.9/lib/python3.9/http/client.py", line 1012, in _send_output
    self.send(msg)
  File "/Library/Developer/CommandLineTools/Library/Frameworks/Python3.framework/Versions/3.9/lib/python3.9/http/client.py", line 952, in send
    self.connect()
  File "/Users/yasinalbayrak/PycharmProjects/djangoProject2/venv/lib/python3.9/site-packages/urllib3/connection.py", line 243, in connect
    self.sock = self._new_conn()
  File "/Users/yasinalbayrak/PycharmProjects/djangoProject2/venv/lib/python3.9/site-packages/urllib3/connection.py", line 218, in _new_conn
    raise NewConnectionError(
urllib3.exceptions.NewConnectionError: <urllib3.connection.HTTPConnection object at 0x1041474c0>: Failed to establish a new connection: [Errno 61] Connection refused

The above exception was the direct cause of the following exception:

Traceback (most recent call last):
  File "/Users/yasinalbayrak/PycharmProjects/djangoProject2/venv/lib/python3.9/site-packages/requests/adapters.py", line 486, in send
    resp = conn.urlopen(
  File "/Users/yasinalbayrak/PycharmProjects/djangoProject2/venv/lib/python3.9/site-packages/urllib3/connectionpool.py", line 844, in urlopen
    retries = retries.increment(
  File "/Users/yasinalbayrak/PycharmProjects/djangoProject2/venv/lib/python3.9/site-packages/urllib3/util/retry.py", line 515, in increment
    raise MaxRetryError(_pool, url, reason) from reason  # type: ignore[arg-type]
urllib3.exceptions.MaxRetryError: HTTPConnectionPool(host='127.0.0.1', port=800): Max retries exceeded with url: / (Caused by NewConnectionError('<urllib3.connection.HTTPConnection object at 0x1041474c0>: Failed to establish a new connection: [Errno 61] Connection refused'))

During handling of the above exception, another exception occurred:

Traceback (most recent call last):
  File "/Users/yasinalbayrak/PycharmProjects/djangoProject2/venv/lib/python3.9/site-packages/django/core/handlers/exception.py", line 55, in inner
    response = get_response(request)
  File "/Users/yasinalbayrak/PycharmProjects/djangoProject2/venv/lib/python3.9/site-packages/django/core/handlers/base.py", line 197, in _get_response
    response = wrapped_callback(request, *callback_args, **callback_kwargs)
  File "/Users/yasinalbayrak/PycharmProjects/djangoProject2/russianNews/views.py", line 272, in get_image
    response = requests.get(image_url, stream=True)
  File "/Users/yasinalbayrak/PycharmProjects/djangoProject2/venv/lib/python3.9/site-packages/requests/api.py", line 73, in get
    return request("get", url, params=params, **kwargs)
  File "/Users/yasinalbayrak/PycharmProjects/djangoProject2/venv/lib/python3.9/site-packages/requests/api.py", line 59, in request
    return session.request(method=method, url=url, **kwargs)
  File "/Users/yasinalbayrak/PycharmProjects/djangoProject2/venv/lib/python3.9/site-packages/requests/sessions.py", line 589, in request
    resp = self.send(prep, **send_kwargs)
  File "/Users/yasinalbayrak/PycharmProjects/djangoProject2/venv/lib/python3.9/site-packages/requests/sessions.py", line 703, in send
    r = adapter.send(request, **kwargs)
  File "/Users/yasinalbayrak/PycharmProjects/djangoProject2/venv/lib/python3.9/site-packages/requests/adapters.py", line 519, in send
    raise ConnectionError(e, request=request)
requests.exceptions.ConnectionError: HTTPConnectionPool(host='127.0.0.1', port=800): Max retries exceeded with url: / (Caused by NewConnectionError('<urllib3.connection.HTTPConnection object at 0x1041474c0>: Failed to establish a new connection: [Errno 61] Connection refused'))
Internal Server Error: /get-image/
Traceback (most recent call last):
  File "/Users/yasinalbayrak/PycharmProjects/djangoProject2/venv/lib/python3.9/site-packages/urllib3/connection.py", line 203, in _new_conn
    sock = connection.create_connection(
  File "/Users/yasinalbayrak/PycharmProjects/djangoProject2/venv/lib/python3.9/site-packages/urllib3/util/connection.py", line 85, in create_connection
    raise err
  File "/Users/yasinalbayrak/PycharmProjects/djangoProject2/venv/lib/python3.9/site-packages/urllib3/util/connection.py", line 73, in create_connection
    sock.connect(sa)
ConnectionRefusedError: [Errno 61] Connection refused

The above exception was the direct cause of the following exception:

Traceback (most recent call last):
  File "/Users/yasinalbayrak/PycharmProjects/djangoProject2/venv/lib/python3.9/site-packages/urllib3/connectionpool.py", line 790, in urlopen
    response = self._make_request(
  File "/Users/yasinalbayrak/PycharmProjects/djangoProject2/venv/lib/python3.9/site-packages/urllib3/connectionpool.py", line 496, in _make_request
    conn.request(
  File "/Users/yasinalbayrak/PycharmProjects/djangoProject2/venv/lib/python3.9/site-packages/urllib3/connection.py", line 395, in request
    self.endheaders()
  File "/Library/Developer/CommandLineTools/Library/Frameworks/Python3.framework/Versions/3.9/lib/python3.9/http/client.py", line 1252, in endheaders
    self._send_output(message_body, encode_chunked=encode_chunked)
  File "/Library/Developer/CommandLineTools/Library/Frameworks/Python3.framework/Versions/3.9/lib/python3.9/http/client.py", line 1012, in _send_output
    self.send(msg)
  File "/Library/Developer/CommandLineTools/Library/Frameworks/Python3.framework/Versions/3.9/lib/python3.9/http/client.py", line 952, in send
    self.connect()
  File "/Users/yasinalbayrak/PycharmProjects/djangoProject2/venv/lib/python3.9/site-packages/urllib3/connection.py", line 243, in connect
    self.sock = self._new_conn()
  File "/Users/yasinalbayrak/PycharmProjects/djangoProject2/venv/lib/python3.9/site-packages/urllib3/connection.py", line 218, in _new_conn
    raise NewConnectionError(
urllib3.exceptions.NewConnectionError: <urllib3.connection.HTTPConnection object at 0x104559340>: Failed to establish a new connection: [Errno 61] Connection refused

The above exception was the direct cause of the following exception:

Traceback (most recent call last):
  File "/Users/yasinalbayrak/PycharmProjects/djangoProject2/venv/lib/python3.9/site-packages/requests/adapters.py", line 486, in send
    resp = conn.urlopen(
  File "/Users/yasinalbayrak/PycharmProjects/djangoProject2/venv/lib/python3.9/site-packages/urllib3/connectionpool.py", line 844, in urlopen
    retries = retries.increment(
  File "/Users/yasinalbayrak/PycharmProjects/djangoProject2/venv/lib/python3.9/site-packages/urllib3/util/retry.py", line 515, in increment
    raise MaxRetryError(_pool, url, reason) from reason  # type: ignore[arg-type]
urllib3.exceptions.MaxRetryError: HTTPConnectionPool(host='127.0.0.1', port=21): Max retries exceeded with url: / (Caused by NewConnectionError('<urllib3.connection.HTTPConnection object at 0x104559340>: Failed to establish a new connection: [Errno 61] Connection refused'))

During handling of the above exception, another exception occurred:

Traceback (most recent call last):
  File "/Users/yasinalbayrak/PycharmProjects/djangoProject2/venv/lib/python3.9/site-packages/django/core/handlers/exception.py", line 55, in inner
    response = get_response(request)
  File "/Users/yasinalbayrak/PycharmProjects/djangoProject2/venv/lib/python3.9/site-packages/django/core/handlers/base.py", line 197, in _get_response
    response = wrapped_callback(request, *callback_args, **callback_kwargs)
  File "/Users/yasinalbayrak/PycharmProjects/djangoProject2/russianNews/views.py", line 272, in get_image
    response = requests.get(image_url, stream=True)
  File "/Users/yasinalbayrak/PycharmProjects/djangoProject2/venv/lib/python3.9/site-packages/requests/api.py", line 73, in get
    return request("get", url, params=params, **kwargs)
  File "/Users/yasinalbayrak/PycharmProjects/djangoProject2/venv/lib/python3.9/site-packages/requests/api.py", line 59, in request
    return session.request(method=method, url=url, **kwargs)
  File "/Users/yasinalbayrak/PycharmProjects/djangoProject2/venv/lib/python3.9/site-packages/requests/sessions.py", line 589, in request
    resp = self.send(prep, **send_kwargs)
  File "/Users/yasinalbayrak/PycharmProjects/djangoProject2/venv/lib/python3.9/site-packages/requests/sessions.py", line 703, in send
    r = adapter.send(request, **kwargs)
  File "/Users/yasinalbayrak/PycharmProjects/djangoProject2/venv/lib/python3.9/site-packages/requests/adapters.py", line 519, in send
    raise ConnectionError(e, request=request)
requests.exceptions.ConnectionError: HTTPConnectionPool(host='127.0.0.1', port=21): Max retries exceeded with url: / (Caused by NewConnectionError('<urllib3.connection.HTTPConnection object at 0x104559340>: Failed to establish a new connection: [Errno 61] Connection refused'))
/Users/yasinalbayrak/PycharmProjects/djangoProject2/russianNews/views.py changed, reloading.
Watching for file changes with StatReloader
Internal Server Error: /get-image/
Traceback (most recent call last):
  File "/Users/yasinalbayrak/PycharmProjects/djangoProject2/venv/lib/python3.9/site-packages/urllib3/connection.py", line 203, in _new_conn
    sock = connection.create_connection(
  File "/Users/yasinalbayrak/PycharmProjects/djangoProject2/venv/lib/python3.9/site-packages/urllib3/util/connection.py", line 85, in create_connection
    raise err
  File "/Users/yasinalbayrak/PycharmProjects/djangoProject2/venv/lib/python3.9/site-packages/urllib3/util/connection.py", line 73, in create_connection
    sock.connect(sa)
ConnectionRefusedError: [Errno 61] Connection refused

The above exception was the direct cause of the following exception:

Traceback (most recent call last):
  File "/Users/yasinalbayrak/PycharmProjects/djangoProject2/venv/lib/python3.9/site-packages/urllib3/connectionpool.py", line 790, in urlopen
    response = self._make_request(
  File "/Users/yasinalbayrak/PycharmProjects/djangoProject2/venv/lib/python3.9/site-packages/urllib3/connectionpool.py", line 496, in _make_request
    conn.request(
  File "/Users/yasinalbayrak/PycharmProjects/djangoProject2/venv/lib/python3.9/site-packages/urllib3/connection.py", line 395, in request
    self.endheaders()
  File "/Library/Developer/CommandLineTools/Library/Frameworks/Python3.framework/Versions/3.9/lib/python3.9/http/client.py", line 1252, in endheaders
    self._send_output(message_body, encode_chunked=encode_chunked)
  File "/Library/Developer/CommandLineTools/Library/Frameworks/Python3.framework/Versions/3.9/lib/python3.9/http/client.py", line 1012, in _send_output
    self.send(msg)
  File "/Library/Developer/CommandLineTools/Library/Frameworks/Python3.framework/Versions/3.9/lib/python3.9/http/client.py", line 952, in send
    self.connect()
  File "/Users/yasinalbayrak/PycharmProjects/djangoProject2/venv/lib/python3.9/site-packages/urllib3/connection.py", line 243, in connect
    self.sock = self._new_conn()
  File "/Users/yasinalbayrak/PycharmProjects/djangoProject2/venv/lib/python3.9/site-packages/urllib3/connection.py", line 218, in _new_conn
    raise NewConnectionError(
urllib3.exceptions.NewConnectionError: <urllib3.connection.HTTPConnection object at 0x107864a60>: Failed to establish a new connection: [Errno 61] Connection refused

The above exception was the direct cause of the following exception:

Traceback (most recent call last):
  File "/Users/yasinalbayrak/PycharmProjects/djangoProject2/venv/lib/python3.9/site-packages/requests/adapters.py", line 486, in send
    resp = conn.urlopen(
  File "/Users/yasinalbayrak/PycharmProjects/djangoProject2/venv/lib/python3.9/site-packages/urllib3/connectionpool.py", line 844, in urlopen
    retries = retries.increment(
  File "/Users/yasinalbayrak/PycharmProjects/djangoProject2/venv/lib/python3.9/site-packages/urllib3/util/retry.py", line 515, in increment
    raise MaxRetryError(_pool, url, reason) from reason  # type: ignore[arg-type]
urllib3.exceptions.MaxRetryError: HTTPConnectionPool(host='127.0.0.1', port=800): Max retries exceeded with url: / (Caused by NewConnectionError('<urllib3.connection.HTTPConnection object at 0x107864a60>: Failed to establish a new connection: [Errno 61] Connection refused'))

During handling of the above exception, another exception occurred:

Traceback (most recent call last):
  File "/Users/yasinalbayrak/PycharmProjects/djangoProject2/russianNews/views.py", line 273, in get_image
    response = requests.get(image_url, stream=True)
  File "/Users/yasinalbayrak/PycharmProjects/djangoProject2/venv/lib/python3.9/site-packages/requests/api.py", line 73, in get
    return request("get", url, params=params, **kwargs)
  File "/Users/yasinalbayrak/PycharmProjects/djangoProject2/venv/lib/python3.9/site-packages/requests/api.py", line 59, in request
    return session.request(method=method, url=url, **kwargs)
  File "/Users/yasinalbayrak/PycharmProjects/djangoProject2/venv/lib/python3.9/site-packages/requests/sessions.py", line 589, in request
    resp = self.send(prep, **send_kwargs)
  File "/Users/yasinalbayrak/PycharmProjects/djangoProject2/venv/lib/python3.9/site-packages/requests/sessions.py", line 703, in send
    r = adapter.send(request, **kwargs)
  File "/Users/yasinalbayrak/PycharmProjects/djangoProject2/venv/lib/python3.9/site-packages/requests/adapters.py", line 519, in send
    raise ConnectionError(e, request=request)
requests.exceptions.ConnectionError: HTTPConnectionPool(host='127.0.0.1', port=800): Max retries exceeded with url: / (Caused by NewConnectionError('<urllib3.connection.HTTPConnection object at 0x107864a60>: Failed to establish a new connection: [Errno 61] Connection refused'))

During handling of the above exception, another exception occurred:

Traceback (most recent call last):
  File "/Users/yasinalbayrak/PycharmProjects/djangoProject2/venv/lib/python3.9/site-packages/urllib3/connection.py", line 203, in _new_conn
    sock = connection.create_connection(
  File "/Users/yasinalbayrak/PycharmProjects/djangoProject2/venv/lib/python3.9/site-packages/urllib3/util/connection.py", line 85, in create_connection
    raise err
  File "/Users/yasinalbayrak/PycharmProjects/djangoProject2/venv/lib/python3.9/site-packages/urllib3/util/connection.py", line 73, in create_connection
    sock.connect(sa)
ConnectionRefusedError: [Errno 61] Connection refused

The above exception was the direct cause of the following exception:

Traceback (most recent call last):
  File "/Users/yasinalbayrak/PycharmProjects/djangoProject2/venv/lib/python3.9/site-packages/urllib3/connectionpool.py", line 790, in urlopen
    response = self._make_request(
  File "/Users/yasinalbayrak/PycharmProjects/djangoProject2/venv/lib/python3.9/site-packages/urllib3/connectionpool.py", line 496, in _make_request
    conn.request(
  File "/Users/yasinalbayrak/PycharmProjects/djangoProject2/venv/lib/python3.9/site-packages/urllib3/connection.py", line 395, in request
    self.endheaders()
  File "/Library/Developer/CommandLineTools/Library/Frameworks/Python3.framework/Versions/3.9/lib/python3.9/http/client.py", line 1252, in endheaders
    self._send_output(message_body, encode_chunked=encode_chunked)
  File "/Library/Developer/CommandLineTools/Library/Frameworks/Python3.framework/Versions/3.9/lib/python3.9/http/client.py", line 1012, in _send_output
    self.send(msg)
  File "/Library/Developer/CommandLineTools/Library/Frameworks/Python3.framework/Versions/3.9/lib/python3.9/http/client.py", line 952, in send
    self.connect()
  File "/Users/yasinalbayrak/PycharmProjects/djangoProject2/venv/lib/python3.9/site-packages/urllib3/connection.py", line 243, in connect
    self.sock = self._new_conn()
  File "/Users/yasinalbayrak/PycharmProjects/djangoProject2/venv/lib/python3.9/site-packages/urllib3/connection.py", line 218, in _new_conn
    raise NewConnectionError(
urllib3.exceptions.NewConnectionError: <urllib3.connection.HTTPConnection object at 0x1078528e0>: Failed to establish a new connection: [Errno 61] Connection refused

The above exception was the direct cause of the following exception:

Traceback (most recent call last):
  File "/Users/yasinalbayrak/PycharmProjects/djangoProject2/venv/lib/python3.9/site-packages/requests/adapters.py", line 486, in send
    resp = conn.urlopen(
  File "/Users/yasinalbayrak/PycharmProjects/djangoProject2/venv/lib/python3.9/site-packages/urllib3/connectionpool.py", line 844, in urlopen
    retries = retries.increment(
  File "/Users/yasinalbayrak/PycharmProjects/djangoProject2/venv/lib/python3.9/site-packages/urllib3/util/retry.py", line 515, in increment
    raise MaxRetryError(_pool, url, reason) from reason  # type: ignore[arg-type]
urllib3.exceptions.MaxRetryError: HTTPConnectionPool(host='127.0.0.1', port=800): Max retries exceeded with url: / (Caused by NewConnectionError('<urllib3.connection.HTTPConnection object at 0x1078528e0>: Failed to establish a new connection: [Errno 61] Connection refused'))

During handling of the above exception, another exception occurred:

Traceback (most recent call last):
  File "/Users/yasinalbayrak/PycharmProjects/djangoProject2/venv/lib/python3.9/site-packages/django/core/handlers/exception.py", line 55, in inner
    response = get_response(request)
  File "/Users/yasinalbayrak/PycharmProjects/djangoProject2/venv/lib/python3.9/site-packages/django/core/handlers/base.py", line 197, in _get_response
    response = wrapped_callback(request, *callback_args, **callback_kwargs)
  File "/Users/yasinalbayrak/PycharmProjects/djangoProject2/russianNews/views.py", line 281, in get_image
    response = requests.get(image_url)
  File "/Users/yasinalbayrak/PycharmProjects/djangoProject2/venv/lib/python3.9/site-packages/requests/api.py", line 73, in get
    return request("get", url, params=params, **kwargs)
  File "/Users/yasinalbayrak/PycharmProjects/djangoProject2/venv/lib/python3.9/site-packages/requests/api.py", line 59, in request
    return session.request(method=method, url=url, **kwargs)
  File "/Users/yasinalbayrak/PycharmProjects/djangoProject2/venv/lib/python3.9/site-packages/requests/sessions.py", line 589, in request
    resp = self.send(prep, **send_kwargs)
  File "/Users/yasinalbayrak/PycharmProjects/djangoProject2/venv/lib/python3.9/site-packages/requests/sessions.py", line 703, in send
    r = adapter.send(request, **kwargs)
  File "/Users/yasinalbayrak/PycharmProjects/djangoProject2/venv/lib/python3.9/site-packages/requests/adapters.py", line 519, in send
    raise ConnectionError(e, request=request)
requests.exceptions.ConnectionError: HTTPConnectionPool(host='127.0.0.1', port=800): Max retries exceeded with url: / (Caused by NewConnectionError('<urllib3.connection.HTTPConnection object at 0x1078528e0>: Failed to establish a new connection: [Errno 61] Connection refused'))
/Users/yasinalbayrak/PycharmProjects/djangoProject2/russianNews/views.py changed, reloading.
Watching for file changes with StatReloader
/Users/yasinalbayrak/PycharmProjects/djangoProject2/russianNews/views.py changed, reloading.
Watching for file changes with StatReloader
/Users/yasinalbayrak/PycharmProjects/djangoProject2/russianNews/views.py changed, reloading.
Watching for file changes with StatReloader
/Users/yasinalbayrak/PycharmProjects/djangoProject2/russianNews/views.py changed, reloading.
Watching for file changes with StatReloader
Watching for file changes with StatReloader
/Users/yasinalbayrak/PycharmProjects/djangoProject2/djangoProject2/urls.py changed, reloading.
Watching for file changes with StatReloader
/Users/yasinalbayrak/PycharmProjects/djangoProject2/russianNews/views.py changed, reloading.
Watching for file changes with StatReloader
/Users/yasinalbayrak/PycharmProjects/djangoProject2/russianNews/views.py changed, reloading.
Watching for file changes with StatReloader
Watching for file changes with StatReloader
Watching for file changes with StatReloader
C:\Users\pc\Desktop\ssrf-project\venv\Lib\site-packages\idna\idnadata.py changed, reloading.
Watching for file changes with StatReloader
Watching for file changes with StatReloader
Not Found: /favicon.ico
Watching for file changes with StatReloader
Not Found: /favicon.ico
Registration failed: Username silaozinan already exists
Watching for file changes with StatReloader
